<mujoco model="onshape">
  <compiler angle="radian" />
  <asset>
    <mesh name="m3_heat_set_insert" file="m3_heat_set_insert.stl" />
    <mesh name="ur5_adaptor" file="ur5_adaptor.stl" />
    <mesh name="ur5_arm_adapter" file="ur5_arm_adapter.stl" />
    <mesh name="palm_lower" file="palm_lower.stl" />
    <mesh name="part_1" file="part_1.stl" />
    <mesh name="palm_base" file="palm_base.stl" />
    <mesh name="palm_upper" file="palm_upper.stl" />
    <mesh name="xm430-w350-part-4" file="xm430-w350-part-4.stl" />
    <mesh name="xm430-w350-part-15" file="xm430-w350-part-15.stl" />
    <mesh name="xm430-w350-part-16" file="xm430-w350-part-16.stl" />
    <mesh name="xm430-w350-part-6" file="xm430-w350-part-6.stl" />
    <mesh name="xm430-w350-part-1" file="xm430-w350-part-1.stl" />
    <mesh name="l1" file="l1.stl" />
    <mesh name="l2" file="l2.stl" />
    <mesh name="tip_shoulder_screw" file="tip_shoulder_screw.stl" />
    <mesh name="finger_backbone" file="finger_backbone.stl" />
    <mesh name="fr12_h101" file="fr12_h101.stl" />
  </asset>
  <option timestep=".001" />

  <extension>
    <plugin plugin="mujoco.elasticity.solid" />
  </extension>
  <worldbody>
    <geom pos="-0.00513595 -0.0213 -0.0100947" quat="0 0 -0.707107 -0.707107" type="mesh"
      rgba="1 0.756863 0.054902 1" mesh="m3_heat_set_insert" />
    <geom pos="0.00582815 0.0006 -0.0100947" quat="0 0 -0.707107 -0.707107" type="mesh"
      rgba="0.45098 0.435294 0.435294 1" mesh="ur5_adaptor" />
    <geom pos="-0.0270718 -0.065194 -0.0100947" quat="0 0.707107 0 -0.707107" type="mesh"
      rgba="0.498039 0.498039 0.498039 1" mesh="ur5_arm_adapter" />
    <geom pos="0.00582815 0.0006 -0.0100947" quat="0 0 0.707107 0.707107" type="mesh"
      rgba="0.301961 0.301961 0.301961 1" mesh="palm_lower" />
    <geom pos="0.0113102 0 -0.000599467" quat="0 0.258819 0 -0.965926" type="mesh"
      rgba="0.752941 0.752941 0.752941 1" mesh="part_1" />
    <geom pos="0.00582815 0.0006 -0.0100947" quat="0 0 -0.707107 -0.707107" type="mesh"
      rgba="0.45098 0.435294 0.435294 1" mesh="palm_base" />
    <geom pos="0.00582815 0.0006 -0.0100947" quat="0.612372 -0.612372 0.353553 0.353553" type="mesh"
      rgba="0.301961 0.301961 0.301961 1" mesh="palm_upper" />
    <geom pos="-0.00513595 0 -0.0100947" quat="0 0.258819 0 -0.965926" type="mesh"
      rgba="0.752941 0.752941 0.752941 1" mesh="part_1" />
    <geom pos="0.0113102 0 -0.0195898" quat="0 0.258819 0 -0.965926" type="mesh"
      rgba="0.752941 0.752941 0.752941 1" mesh="part_1" />
    <geom pos="0.0651041 0.0262755 -0.0106865" quat="0 0 1 0" type="mesh"
      rgba="0.25098 0.25098 0.25098 1" mesh="xm430-w350-part-4" />
    <geom pos="0.0545229 0.0400458 -0.0106865" quat="0 -0.766044 -0.642788 0" type="mesh"
      rgba="0.752941 0.752941 0.752941 1" mesh="xm430-w350-part-15" />
    <geom pos="0.0651041 0.0262755 -0.0106865" quat="0 0 1 0" type="mesh"
      rgba="0.25098 0.25098 0.25098 1" mesh="xm430-w350-part-16" />
    <geom pos="0.0651041 0.0262755 -0.0106865" quat="0 0 1 0" type="mesh"
      rgba="0.25098 0.25098 0.25098 1" mesh="xm430-w350-part-6" />
    <geom pos="0.0545229 0.0400458 -0.00968646" quat="0 0.766044 0.642788 0" type="mesh"
      rgba="0.752941 0.752941 0.752941 1" mesh="xm430-w350-part-1" />
    <geom pos="-0.0232973 0.0262755 0.0415357" quat="0.866025 0 0.5 0" type="mesh"
      rgba="0.25098 0.25098 0.25098 1" mesh="xm430-w350-part-4" />
    <geom pos="-0.0180067 0.0400458 0.0323721" quat="0.55667 0.383022 0.321394 0.663414" type="mesh"
      rgba="0.752941 0.752941 0.752941 1" mesh="xm430-w350-part-15" />
    <geom pos="-0.0232973 0.0262755 0.0415357" quat="0.866025 0 0.5 0" type="mesh"
      rgba="0.25098 0.25098 0.25098 1" mesh="xm430-w350-part-16" />
    <geom pos="-0.0232973 0.0262755 0.0415357" quat="0.866025 0 0.5 0" type="mesh"
      rgba="0.25098 0.25098 0.25098 1" mesh="xm430-w350-part-6" />
    <geom pos="-0.0188727 0.0400458 0.0318721" quat="0.55667 0.383022 0.321394 0.663414" type="mesh"
      rgba="0.752941 0.752941 0.752941 1" mesh="xm430-w350-part-1" />
    <geom pos="-0.0243223 0.0262755 -0.0611332" quat="0.866025 0 -0.5 0" type="mesh"
      rgba="0.25098 0.25098 0.25098 1" mesh="xm430-w350-part-4" />
    <geom pos="-0.0190317 0.0400458 -0.0519696" quat="0.55667 -0.383022 -0.321394 0.663414"
      type="mesh" rgba="0.752941 0.752941 0.752941 1" mesh="xm430-w350-part-15" />
    <geom pos="-0.0243223 0.0262755 -0.0611332" quat="0.866025 0 -0.5 0" type="mesh"
      rgba="0.25098 0.25098 0.25098 1" mesh="xm430-w350-part-16" />
    <geom pos="-0.0243223 0.0262755 -0.0611332" quat="0.866025 0 -0.5 0" type="mesh"
      rgba="0.25098 0.25098 0.25098 1" mesh="xm430-w350-part-6" />
    <geom pos="-0.0181657 0.0400458 -0.0524696" quat="0.55667 -0.383022 -0.321394 0.663414"
      type="mesh" rgba="0.752941 0.752941 0.752941 1" mesh="xm430-w350-part-1" />
    <body name="finger_assembly_-_main" pos="-0.00759867 0.0376 0.0511613"
      quat="0.383022 -0.55667 -0.663414 0.321394">
      <inertial pos="0.0630768 -0.0184822 0.0189935" quat="0.0800809 0.702777 -0.0795419 0.702399"
        mass="0.034647" diaginertia="5.2637e-05 4.90863e-05 1.16822e-05" />
      <joint name="finger1" pos="0 0 0" axis="0 0 1" actuatorfrcrange="-1 1" />
      <geom pos="0.05 -0.0719985 0.004" quat="0.707107 0 0 -0.707107" type="mesh"
        rgba="0.301961 0.301961 0.301961 1" mesh="l1" />
      <geom pos="0.05 -0.0719985 0.004" quat="0.707107 0 0 -0.707107" type="mesh"
        rgba="0.301961 0.301961 0.301961 1" mesh="l2" />
      <geom pos="0.05 -0.0719985 0.004" quat="0.707107 0 0 -0.707107" type="mesh"
        rgba="0.752941 0.752941 0.752941 1" mesh="tip_shoulder_screw" />

      <flexcomp name = "flex_finger" pos="0.0498 -0.0722622 0.004" quat="0.707107 0 0 -0.707107" type="gmsh"
      rgba="0.45098 0.435294 0.435294 1" file="finger6.1_vol.msh">
        <contact condim="6" solref="0.01 1" solimp=".95 .99 .0001" selfcollide="none" />
        <edge damping="1" />
        <plugin plugin="mujoco.elasticity.solid">
          <config key="poisson" value="0.2" />
          <!--Units
          are in Pa (SI)-->
          <config key="young" value="5e4" />
        </plugin>
      </flexcomp>
      <geom pos="0 0 0.019" quat="0.5 -0.5 -0.5 -0.5" type="mesh" rgba="0 0 0 1" mesh="fr12_h101" />
    </body>
    <body name="finger_assembly_-_main_2" pos="0.0655908 0.0376 -0.0290947"
      quat="0.766044 0 0 0.642788">
      <inertial pos="0.0630768 -0.0184822 0.0189935" quat="0.0800809 0.702777 -0.0795419 0.702399"
        mass="0.034647" diaginertia="5.2637e-05 4.90863e-05 1.16822e-05" />
      <joint name="finger2" pos="0 0 0" axis="0 0 1" actuatorfrcrange="-1 1" />
      <geom pos="0.05 -0.0719985 0.004" quat="0.707107 0 0 -0.707107" type="mesh"
        rgba="0.301961 0.301961 0.301961 1" mesh="l1" />
      <geom pos="0.05 -0.0719985 0.004" quat="0.707107 0 0 -0.707107" type="mesh"
        rgba="0.301961 0.301961 0.301961 1" mesh="l2" />
      <geom pos="0.05 -0.0719985 0.004" quat="0.707107 0 0 -0.707107" type="mesh"
        rgba="0.752941 0.752941 0.752941 1" mesh="tip_shoulder_screw" />
      <geom pos="0.0498 -0.0722622 0.004" quat="0.707107 0 0 -0.707107" type="mesh"
        rgba="0.45098 0.435294 0.435294 1" mesh="finger_backbone" />
      <geom pos="0 0 0.019" quat="0.5 -0.5 -0.5 -0.5" type="mesh" rgba="0 0 0 1" mesh="fr12_h101" />
    </body>
    <body name="finger_assembly_-_main_3" pos="-0.0405076 0.0376 -0.0523506"
      quat="0.383022 0.55667 0.663414 0.321394">
      <inertial pos="0.0630768 -0.0184822 0.0189935" quat="0.0800809 0.702777 -0.0795419 0.702399"
        mass="0.034647" diaginertia="5.2637e-05 4.90863e-05 1.16822e-05" />
      <joint name="finger3" pos="0 0 0" axis="0 0 1" actuatorfrcrange="-1 1" />
      <geom pos="0.05 -0.0719985 0.004" quat="0.707107 0 0 -0.707107" type="mesh"
        rgba="0.301961 0.301961 0.301961 1" mesh="l1" />
      <geom pos="0.05 -0.0719985 0.004" quat="0.707107 0 0 -0.707107" type="mesh"
        rgba="0.301961 0.301961 0.301961 1" mesh="l2" />
      <geom pos="0.05 -0.0719985 0.004" quat="0.707107 0 0 -0.707107" type="mesh"
        rgba="0.752941 0.752941 0.752941 1" mesh="tip_shoulder_screw" />
      <geom pos="0.0498 -0.0722622 0.004" quat="0.707107 0 0 -0.707107" type="mesh"
        rgba="0.45098 0.435294 0.435294 1" mesh="finger_backbone" />
      <geom pos="0 0 0.019" quat="0.5 -0.5 -0.5 -0.5" type="mesh" rgba="0 0 0 1" mesh="fr12_h101" />
    </body>
  </worldbody>
</mujoco>