<mujoco model="onshape">
  <compiler angle="radian" />
  <asset>
    <mesh name="m3_heat_set_insert" file="m3_heat_set_insert.stl" scale="100 100 100"/>
    <mesh name="ur5_adaptor" file="ur5_adaptor.stl" scale="100 100 100"/>
    <mesh name="ur5_arm_adapter" file="ur5_arm_adapter.stl" scale="100 100 100"/>
    <mesh name="palm_lower" file="palm_lower.stl" scale="100 100 100"/>
    <mesh name="part_1" file="part_1.stl" scale="100 100 100"/>
    <mesh name="palm_base" file="palm_base.stl" scale="100 100 100"/>
    <mesh name="palm_upper" file="palm_upper.stl" scale="100 100 100"/>
    <mesh name="xm430-w350-part-4" file="xm430-w350-part-4.stl" scale="100 100 100"/>
    <mesh name="xm430-w350-part-15" file="xm430-w350-part-15.stl" scale="100 100 100"/>
    <mesh name="xm430-w350-part-16" file="xm430-w350-part-16.stl" scale="100 100 100"/>
    <mesh name="xm430-w350-part-6" file="xm430-w350-part-6.stl" scale="100 100 100"/>
    <mesh name="xm430-w350-part-1" file="xm430-w350-part-1.stl" scale="100 100 100"/>
    <mesh name="l1" file="l1.stl" scale="100 100 100"/>
    <mesh name="l2" file="l2.stl" scale="100 100 100"/>
    <mesh name="tip_shoulder_screw" file="tip_shoulder_screw.stl" scale="100 100 100"/>
    <mesh name="finger_backbone" file="finger_backbone.stl" scale="100 100 100"/>
    <mesh name="fr12_h101" file="fr12_h101.stl" scale="100 100 100"/>
  </asset>
  
  <asset>
    <texture name="grid" type="2d" builtin="checker" rgb1=".1 .2 .3" rgb2=".2 .3 .4" width="300" height="300" mark="edge" markrgb=".2 .3 .4" />
    <material name="grid" texture="grid" texrepeat="2 2" texuniform="true" reflectance=".2" />
  </asset>
  <option solver="CG" tolerance="1e-6" timestep=".0005" integrator="implicitfast"/>

  <extension>
    <plugin plugin="mujoco.elasticity.solid" />
  </extension>
  <worldbody>
    <geom name="ground" type="plane" pos="0.0 0.0 -50.0" size="2 2 .1" material="grid" solimp=".99 .99 .01" solref=".001 1" />

    <geom pos="-0.513595 -2.13 -1.00947" quat="0 0 -0.707107 -0.707107" type="mesh" rgba="1 0.756863 0.054902 1" mesh="m3_heat_set_insert" />
    <geom pos="0.582815 0.06 -1.00947" quat="0 0 -0.707107 -0.707107" type="mesh" rgba="0.45098 0.435294 0.435294 1" mesh="ur5_adaptor" />
    <geom pos="-2.70718 -6.5194 -1.00947" quat="0 0.707107 0 -0.707107" type="mesh" rgba="0.498039 0.498039 0.498039 1" mesh="ur5_arm_adapter" />
    <geom pos="0.582815 0.06 -1.00947" quat="0 0 0.707107 0.707107" type="mesh" rgba="0.301961 0.301961 0.301961 1" mesh="palm_lower" />
    <geom pos="1.13102 0.0 -0.0599467" quat="0 0.258819 0 -0.965926" type="mesh" rgba="0.752941 0.752941 0.752941 1" mesh="part_1" />
    <geom pos="0.582815 0.06 -1.00947" quat="0 0 -0.707107 -0.707107" type="mesh" rgba="0.45098 0.435294 0.435294 1" mesh="palm_base" />
    <geom pos="0.582815 0.06 -1.00947" quat="0.612372 -0.612372 0.353553 0.353553" type="mesh" rgba="0.301961 0.301961 0.301961 1" mesh="palm_upper" />
    <geom pos="-0.513595 0.0 -1.00947" quat="0 0.258819 0 -0.965926" type="mesh" rgba="0.752941 0.752941 0.752941 1" mesh="part_1" />
    <geom pos="1.13102 0.0 -1.9589800000000002" quat="0 0.258819 0 -0.965926" type="mesh" rgba="0.752941 0.752941 0.752941 1" mesh="part_1" />
    <geom pos="6.51041 2.62755 -1.0686499999999999" quat="0 0 1 0" type="mesh" rgba="0.25098 0.25098 0.25098 1" mesh="xm430-w350-part-4" />
    <geom pos="5.45229 4.00458 -1.0686499999999999" quat="0 -0.766044 -0.642788 0" type="mesh" rgba="0.752941 0.752941 0.752941 1" mesh="xm430-w350-part-15" />
    <geom pos="6.51041 2.62755 -1.0686499999999999" quat="0 0 1 0" type="mesh" rgba="0.25098 0.25098 0.25098 1" mesh="xm430-w350-part-16" />
    <geom pos="6.51041 2.62755 -1.0686499999999999" quat="0 0 1 0" type="mesh" rgba="0.25098 0.25098 0.25098 1" mesh="xm430-w350-part-6" />
    <geom pos="5.45229 4.00458 -0.9686459999999999" quat="0 0.766044 0.642788 0" type="mesh" rgba="0.752941 0.752941 0.752941 1" mesh="xm430-w350-part-1" />
    <geom pos="-2.32973 2.62755 4.15357" quat="0.866025 0 0.5 0" type="mesh" rgba="0.25098 0.25098 0.25098 1" mesh="xm430-w350-part-4" />
    <geom pos="-1.80067 4.00458 3.23721" quat="0.55667 0.383022 0.321394 0.663414" type="mesh" rgba="0.752941 0.752941 0.752941 1" mesh="xm430-w350-part-15" />
    <geom pos="-2.32973 2.62755 4.15357" quat="0.866025 0 0.5 0" type="mesh" rgba="0.25098 0.25098 0.25098 1" mesh="xm430-w350-part-16" />
    <geom pos="-2.32973 2.62755 4.15357" quat="0.866025 0 0.5 0" type="mesh" rgba="0.25098 0.25098 0.25098 1" mesh="xm430-w350-part-6" />
    <geom pos="-1.88727 4.00458 3.18721" quat="0.55667 0.383022 0.321394 0.663414" type="mesh" rgba="0.752941 0.752941 0.752941 1" mesh="xm430-w350-part-1" />
    <geom pos="-2.43223 2.62755 -6.11332" quat="0.866025 0 -0.5 0" type="mesh" rgba="0.25098 0.25098 0.25098 1" mesh="xm430-w350-part-4" />
    <geom pos="-1.9031699999999998 4.00458 -5.19696" quat="0.55667 -0.383022 -0.321394 0.663414" type="mesh" rgba="0.752941 0.752941 0.752941 1" mesh="xm430-w350-part-15" />
    <geom pos="-2.43223 2.62755 -6.11332" quat="0.866025 0 -0.5 0" type="mesh" rgba="0.25098 0.25098 0.25098 1" mesh="xm430-w350-part-16" />
    <geom pos="-2.43223 2.62755 -6.11332" quat="0.866025 0 -0.5 0" type="mesh" rgba="0.25098 0.25098 0.25098 1" mesh="xm430-w350-part-6" />
    <geom pos="-1.81657 4.00458 -5.24696" quat="0.55667 -0.383022 -0.321394 0.663414" type="mesh" rgba="0.752941 0.752941 0.752941 1" mesh="xm430-w350-part-1" />
    <body name="finger_assembly_-_main" pos="-0.759867 3.7600000000000002 5.11613" quat="0.383022 -0.55667 -0.663414 0.321394">
      <inertial pos="6.30768 -1.84822 1.89935" quat="0.0800809 0.702777 -0.0795419 0.702399" mass="0.034647" diaginertia="5.2637e-05 4.90863e-05 1.16822e-05" />
      <joint name="finger1" pos="0.0 0.0 0.0" axis="0 0 1" actuatorfrcrange="-1 1" />
      <geom pos="5.0 -7.1998500000000005 0.4" quat="0.707107 0 0 -0.707107" type="mesh" rgba="0.301961 0.301961 0.301961 1" mesh="l1" />
      <geom pos="5.0 -7.1998500000000005 0.4" quat="0.707107 0 0 -0.707107" type="mesh" rgba="0.301961 0.301961 0.301961 1" mesh="l2" />
      <geom pos="5.0 -7.1998500000000005 0.4" quat="0.707107 0 0 -0.707107" type="mesh" rgba="0.752941 0.752941 0.752941 1" mesh="tip_shoulder_screw" />

      <flexcomp name="flex_finger" pos="4.9799999999999995 -7.22622 0.4" quat="0.707107 0 0 -0.707107" type="gmsh" rgba="0.45098 0.435294 0.435294 1" file="finger6.1_vol.msh" scale=".1 .1 .1">
        <contact condim="6" solref="0.01 1" solimp=".95 .99 .0001" selfcollide="none" />
        <edge damping="50.0" equality="true" />
        <plugin plugin="mujoco.elasticity.solid">
          <config key="poisson" value="0.2" />
          
          <config key="young" value="5e4" />
        </plugin>
      </flexcomp>
      <geom pos="0.0 0.0 1.9" quat="0.5 -0.5 -0.5 -0.5" type="mesh" rgba="0 0 0 1" mesh="fr12_h101" />
    </body>
    <body name="finger_assembly_-_main_2" pos="6.559080000000001 3.7600000000000002 -2.9094700000000002" quat="0.766044 0 0 0.642788">
      <inertial pos="6.30768 -1.84822 1.89935" quat="0.0800809 0.702777 -0.0795419 0.702399" mass="0.034647" diaginertia="5.2637e-05 4.90863e-05 1.16822e-05" />
      <joint name="finger2" pos="0.0 0.0 0.0" axis="0 0 1" actuatorfrcrange="-1 1" />
      <geom pos="5.0 -7.1998500000000005 0.4" quat="0.707107 0 0 -0.707107" type="mesh" rgba="0.301961 0.301961 0.301961 1" mesh="l1" />
      <geom pos="5.0 -7.1998500000000005 0.4" quat="0.707107 0 0 -0.707107" type="mesh" rgba="0.301961 0.301961 0.301961 1" mesh="l2" />
      <geom pos="5.0 -7.1998500000000005 0.4" quat="0.707107 0 0 -0.707107" type="mesh" rgba="0.752941 0.752941 0.752941 1" mesh="tip_shoulder_screw" />
      <geom pos="4.9799999999999995 -7.22622 0.4" quat="0.707107 0 0 -0.707107" type="mesh" rgba="0.45098 0.435294 0.435294 1" mesh="finger_backbone" />
      <geom pos="0.0 0.0 1.9" quat="0.5 -0.5 -0.5 -0.5" type="mesh" rgba="0 0 0 1" mesh="fr12_h101" />
    </body>
    <body name="finger_assembly_-_main_3" pos="-4.0507599999999995 3.7600000000000002 -5.23506" quat="0.383022 0.55667 0.663414 0.321394">
      <inertial pos="6.30768 -1.84822 1.89935" quat="0.0800809 0.702777 -0.0795419 0.702399" mass="0.034647" diaginertia="5.2637e-05 4.90863e-05 1.16822e-05" />
      <joint name="finger3" pos="0.0 0.0 0.0" axis="0 0 1" actuatorfrcrange="-1 1" />
      <geom pos="5.0 -7.1998500000000005 0.4" quat="0.707107 0 0 -0.707107" type="mesh" rgba="0.301961 0.301961 0.301961 1" mesh="l1" />
      <geom pos="5.0 -7.1998500000000005 0.4" quat="0.707107 0 0 -0.707107" type="mesh" rgba="0.301961 0.301961 0.301961 1" mesh="l2" />
      <geom pos="5.0 -7.1998500000000005 0.4" quat="0.707107 0 0 -0.707107" type="mesh" rgba="0.752941 0.752941 0.752941 1" mesh="tip_shoulder_screw" />
      <geom pos="4.9799999999999995 -7.22622 0.4" quat="0.707107 0 0 -0.707107" type="mesh" rgba="0.45098 0.435294 0.435294 1" mesh="finger_backbone" />
      <geom pos="0.0 0.0 1.9" quat="0.5 -0.5 -0.5 -0.5" type="mesh" rgba="0 0 0 1" mesh="fr12_h101" />
    </body>
  </worldbody>
</mujoco>