<robot name="onshape">
<link name="palm_-_assembly_cross_bar">
<visual>
<origin xyz="-0.0051359481293799386092 -0.02129999999999999255 -0.010094657951642164312" rpy="1.570796326794896558 -5.5511151231257790043e-17 -3.141592653589793116" />
<geometry>
<mesh filename="package:///m3_heat_set_insert.stl"/>
</geometry>
<material name="m3_heat_set_insert_material">
<color rgba="1 0.7568627450980391913 0.054901960784313724728 1.0"/>
</material>
</visual>
<collision>
<origin xyz="-0.0051359481293799386092 -0.02129999999999999255 -0.010094657951642164312" rpy="1.570796326794896558 -5.5511151231257790043e-17 -3.141592653589793116" />
<geometry>
<mesh filename="package:///m3_heat_set_insert.stl"/>
</geometry>
</collision>
<visual>
<origin xyz="0.0058281534857578054867 0.00059999999999999983902 -0.010094657951642162577" rpy="1.570796326794896558 1.1539026804736278144e-49 -3.141592653589793116" />
<geometry>
<mesh filename="package:///ur5_adaptor.stl"/>
</geometry>
<material name="ur5_adaptor_material">
<color rgba="0.45098039215686275272 0.43529411764705883137 0.43529411764705883137 1.0"/>
</material>
</visual>
<collision>
<origin xyz="0.0058281534857578054867 0.00059999999999999983902 -0.010094657951642162577" rpy="1.570796326794896558 1.1539026804736278144e-49 -3.141592653589793116" />
<geometry>
<mesh filename="package:///ur5_adaptor.stl"/>
</geometry>
</collision>
<visual>
<origin xyz="-0.027071846514242228765 -0.065194008889998267264 -0.010094657951642140026" rpy="3.141592653589793116 1.5707963267948954478 0" />
<geometry>
<mesh filename="package:///ur5_arm_adapter.stl"/>
</geometry>
<material name="ur5_arm_adapter_material">
<color rgba="0.49803921568627451677 0.49803921568627451677 0.49803921568627451677 1.0"/>
</material>
</visual>
<collision>
<origin xyz="-0.027071846514242228765 -0.065194008889998267264 -0.010094657951642140026" rpy="3.141592653589793116 1.5707963267948954478 0" />
<geometry>
<mesh filename="package:///ur5_arm_adapter.stl"/>
</geometry>
</collision>
<visual>
<origin xyz="0.0058281534857578080888 0.00059999999999999983902 -0.010094657951642162577" rpy="1.570796326794896558 -0 3.141592653589793116" />
<geometry>
<mesh filename="package:///palm_lower.stl"/>
</geometry>
<material name="palm_lower_material">
<color rgba="0.30196078431372547213 0.30196078431372547213 0.30196078431372547213 1.0"/>
</material>
</visual>
<collision>
<origin xyz="0.0058281534857578080888 0.00059999999999999983902 -0.010094657951642162577" rpy="1.570796326794896558 -0 3.141592653589793116" />
<geometry>
<mesh filename="package:///palm_lower.stl"/>
</geometry>
</collision>
<visual>
<origin xyz="0.011310204293326686642 6.9388939039072283776e-18 -0.00059946742325885484307" rpy="-5.0868912798280362883e-17 0.52359877559829859361 -3.141592653589793116" />
<geometry>
<mesh filename="package:///part_1.stl"/>
</geometry>
<material name="part_1_material">
<color rgba="0.75294117647058822484 0.75294117647058822484 0.75294117647058822484 1.0"/>
</material>
</visual>
<collision>
<origin xyz="0.011310204293326686642 6.9388939039072283776e-18 -0.00059946742325885484307" rpy="-5.0868912798280362883e-17 0.52359877559829859361 -3.141592653589793116" />
<geometry>
<mesh filename="package:///part_1.stl"/>
</geometry>
</collision>
<visual>
<origin xyz="0.0058281534857578072215 0.00059999999999999983902 -0.010094657951642164312" rpy="1.570796326794896558 1.6653345369377348106e-16 -3.141592653589793116" />
<geometry>
<mesh filename="package:///palm_base.stl"/>
</geometry>
<material name="palm_base_material">
<color rgba="0.45098039215686275272 0.43529411764705883137 0.43529411764705883137 1.0"/>
</material>
</visual>
<collision>
<origin xyz="0.0058281534857578072215 0.00059999999999999983902 -0.010094657951642164312" rpy="1.570796326794896558 1.6653345369377348106e-16 -3.141592653589793116" />
<geometry>
<mesh filename="package:///palm_base.stl"/>
</geometry>
</collision>
<visual>
<origin xyz="0.0058281534857577976805 0.00059999999999999983902 -0.010094657951642160842" rpy="-1.570796326794896336 1.0471975511965978534 4.4135786246137108617e-16" />
<geometry>
<mesh filename="package:///palm_upper.stl"/>
</geometry>
<material name="palm_upper_material">
<color rgba="0.30196078431372547213 0.30196078431372547213 0.30196078431372547213 1.0"/>
</material>
</visual>
<collision>
<origin xyz="0.0058281534857577976805 0.00059999999999999983902 -0.010094657951642160842" rpy="-1.570796326794896336 1.0471975511965978534 4.4135786246137108617e-16" />
<geometry>
<mesh filename="package:///palm_upper.stl"/>
</geometry>
</collision>
<visual>
<origin xyz="-0.0051359481293799733037 2.0816681711721685133e-17 -0.010094657951642146965" rpy="-5.0868912798280775803e-17 0.52359877559829859361 -3.141592653589793116" />
<geometry>
<mesh filename="package:///part_1.stl"/>
</geometry>
<material name="part_1_material">
<color rgba="0.75294117647058822484 0.75294117647058822484 0.75294117647058822484 1.0"/>
</material>
</visual>
<collision>
<origin xyz="-0.0051359481293799733037 2.0816681711721685133e-17 -0.010094657951642146965" rpy="-5.0868912798280775803e-17 0.52359877559829859361 -3.141592653589793116" />
<geometry>
<mesh filename="package:///part_1.stl"/>
</geometry>
</collision>
<visual>
<origin xyz="0.01131020429332670052 1.7347234759768070944e-17 -0.019589848480025456867" rpy="-5.0868912798280775803e-17 0.52359877559829859361 -3.141592653589793116" />
<geometry>
<mesh filename="package:///part_1.stl"/>
</geometry>
<material name="part_1_material">
<color rgba="0.75294117647058822484 0.75294117647058822484 0.75294117647058822484 1.0"/>
</material>
</visual>
<collision>
<origin xyz="0.01131020429332670052 1.7347234759768070944e-17 -0.019589848480025456867" rpy="-5.0868912798280775803e-17 0.52359877559829859361 -3.141592653589793116" />
<geometry>
<mesh filename="package:///part_1.stl"/>
</geometry>
</collision>
<visual>
<origin xyz="0.065104050798349827334 0.026275538443885547435 -0.010686456684108714549" rpy="-3.141592653589793116 1.0204255741039999316e-16 -3.141592653589793116" />
<geometry>
<mesh filename="package:///xm430-w350-part-4.stl"/>
</geometry>
<material name="xm430-w350-part-4_material">
<color rgba="0.25098039215686274161 0.25098039215686274161 0.25098039215686274161 1.0"/>
</material>
</visual>
<collision>
<origin xyz="0.065104050798349827334 0.026275538443885547435 -0.010686456684108714549" rpy="-3.141592653589793116 1.0204255741039999316e-16 -3.141592653589793116" />
<geometry>
<mesh filename="package:///xm430-w350-part-4.stl"/>
</geometry>
</collision>
<visual>
<origin xyz="0.054522867345334888323 0.040045794422456607031 -0.010686456684108410972" rpy="-3.141592653589793116 2.3439563924394522516e-16 1.3962634016856976249" />
<geometry>
<mesh filename="package:///xm430-w350-part-15.stl"/>
</geometry>
<material name="xm430-w350-part-15_material">
<color rgba="0.75294117647058822484 0.75294117647058822484 0.75294117647058822484 1.0"/>
</material>
</visual>
<collision>
<origin xyz="0.054522867345334888323 0.040045794422456607031 -0.010686456684108410972" rpy="-3.141592653589793116 2.3439563924394522516e-16 1.3962634016856976249" />
<geometry>
<mesh filename="package:///xm430-w350-part-15.stl"/>
</geometry>
</collision>
<visual>
<origin xyz="0.065104050798349827334 0.026275538443885547435 -0.010686456684108714549" rpy="-3.141592653589793116 1.0204255741039999316e-16 -3.141592653589793116" />
<geometry>
<mesh filename="package:///xm430-w350-part-16.stl"/>
</geometry>
<material name="xm430-w350-part-16_material">
<color rgba="0.25098039215686274161 0.25098039215686274161 0.25098039215686274161 1.0"/>
</material>
</visual>
<collision>
<origin xyz="0.065104050798349827334 0.026275538443885547435 -0.010686456684108714549" rpy="-3.141592653589793116 1.0204255741039999316e-16 -3.141592653589793116" />
<geometry>
<mesh filename="package:///xm430-w350-part-16.stl"/>
</geometry>
</collision>
<visual>
<origin xyz="0.065104050798349827334 0.026275538443885547435 -0.010686456684108714549" rpy="-3.141592653589793116 1.0204255741039999316e-16 -3.141592653589793116" />
<geometry>
<mesh filename="package:///xm430-w350-part-6.stl"/>
</geometry>
<material name="xm430-w350-part-6_material">
<color rgba="0.25098039215686274161 0.25098039215686274161 0.25098039215686274161 1.0"/>
</material>
</visual>
<collision>
<origin xyz="0.065104050798349827334 0.026275538443885547435 -0.010686456684108714549" rpy="-3.141592653589793116 1.0204255741039999316e-16 -3.141592653589793116" />
<geometry>
<mesh filename="package:///xm430-w350-part-6.stl"/>
</geometry>
</collision>
<visual>
<origin xyz="0.054522867345334957712 0.040045794422456607031 -0.0096864566841089964205" rpy="3.141592653589793116 1.4056453237509253607e-16 1.3962634016856947383" />
<geometry>
<mesh filename="package:///xm430-w350-part-1.stl"/>
</geometry>
<material name="xm430-w350-part-1_material">
<color rgba="0.75294117647058822484 0.75294117647058822484 0.75294117647058822484 1.0"/>
</material>
</visual>
<collision>
<origin xyz="0.054522867345334957712 0.040045794422456607031 -0.0096864566841089964205" rpy="3.141592653589793116 1.4056453237509253607e-16 1.3962634016856947383" />
<geometry>
<mesh filename="package:///xm430-w350-part-1.stl"/>
</geometry>
</collision>
<visual>
<origin xyz="-0.023297282434294724202 0.026275538443885550904 0.041535674319413129485" rpy="2.7054921343562968175e-16 1.0471975511965974093 4.4135786246138794807e-16" />
<geometry>
<mesh filename="package:///xm430-w350-part-4.stl"/>
</geometry>
<material name="xm430-w350-part-4_material">
<color rgba="0.25098039215686274161 0.25098039215686274161 0.25098039215686274161 1.0"/>
</material>
</visual>
<collision>
<origin xyz="-0.023297282434294724202 0.026275538443885550904 0.041535674319413129485" rpy="2.7054921343562968175e-16 1.0471975511965974093 4.4135786246138794807e-16" />
<geometry>
<mesh filename="package:///xm430-w350-part-4.stl"/>
</geometry>
</collision>
<visual>
<origin xyz="-0.018006690707787025713 0.040045794422456669481 0.032372100646998303031" rpy="1.04054339367726989 -0.15095640855802758273 1.6587324507724450218" />
<geometry>
<mesh filename="package:///xm430-w350-part-15.stl"/>
</geometry>
<material name="xm430-w350-part-15_material">
<color rgba="0.75294117647058822484 0.75294117647058822484 0.75294117647058822484 1.0"/>
</material>
</visual>
<collision>
<origin xyz="-0.018006690707787025713 0.040045794422456669481 0.032372100646998303031" rpy="1.04054339367726989 -0.15095640855802758273 1.6587324507724450218" />
<geometry>
<mesh filename="package:///xm430-w350-part-15.stl"/>
</geometry>
</collision>
<visual>
<origin xyz="-0.023297282434294724202 0.026275538443885550904 0.041535674319413129485" rpy="2.7054921343562968175e-16 1.0471975511965974093 4.4135786246138794807e-16" />
<geometry>
<mesh filename="package:///xm430-w350-part-16.stl"/>
</geometry>
<material name="xm430-w350-part-16_material">
<color rgba="0.25098039215686274161 0.25098039215686274161 0.25098039215686274161 1.0"/>
</material>
</visual>
<collision>
<origin xyz="-0.023297282434294724202 0.026275538443885550904 0.041535674319413129485" rpy="2.7054921343562968175e-16 1.0471975511965974093 4.4135786246138794807e-16" />
<geometry>
<mesh filename="package:///xm430-w350-part-16.stl"/>
</geometry>
</collision>
<visual>
<origin xyz="-0.023297282434294724202 0.026275538443885550904 0.041535674319413129485" rpy="2.7054921343562968175e-16 1.0471975511965974093 4.4135786246138794807e-16" />
<geometry>
<mesh filename="package:///xm430-w350-part-6.stl"/>
</geometry>
<material name="xm430-w350-part-6_material">
<color rgba="0.25098039215686274161 0.25098039215686274161 0.25098039215686274161 1.0"/>
</material>
</visual>
<collision>
<origin xyz="-0.023297282434294724202 0.026275538443885550904 0.041535674319413129485" rpy="2.7054921343562968175e-16 1.0471975511965974093 4.4135786246138794807e-16" />
<geometry>
<mesh filename="package:///xm430-w350-part-6.stl"/>
</geometry>
</collision>
<visual>
<origin xyz="-0.018872716111571468528 0.040045794422456627848 0.031872100646998309526" rpy="1.0405433936772694459 -0.15095640855802763824 1.6587324507724441336" />
<geometry>
<mesh filename="package:///xm430-w350-part-1.stl"/>
</geometry>
<material name="xm430-w350-part-1_material">
<color rgba="0.75294117647058822484 0.75294117647058822484 0.75294117647058822484 1.0"/>
</material>
</visual>
<collision>
<origin xyz="-0.018872716111571468528 0.040045794422456627848 0.031872100646998309526" rpy="1.0405433936772694459 -0.15095640855802763824 1.6587324507724441336" />
<geometry>
<mesh filename="package:///xm430-w350-part-1.stl"/>
</geometry>
</collision>
<visual>
<origin xyz="-0.024322307906781324982 0.026275538443885554374 -0.061133191490231088283" rpy="-7.038361752181275163e-18 -1.0471975511965980754 5.1698788284564264118e-26" />
<geometry>
<mesh filename="package:///xm430-w350-part-4.stl"/>
</geometry>
<material name="xm430-w350-part-4_material">
<color rgba="0.25098039215686274161 0.25098039215686274161 0.25098039215686274161 1.0"/>
</material>
</visual>
<collision>
<origin xyz="-0.024322307906781324982 0.026275538443885554374 -0.061133191490231088283" rpy="-7.038361752181275163e-18 -1.0471975511965980754 5.1698788284564264118e-26" />
<geometry>
<mesh filename="package:///xm430-w350-part-4.stl"/>
</geometry>
</collision>
<visual>
<origin xyz="-0.019031716180273727107 0.040045794422456669481 -0.051969617817816123051" rpy="-1.0405433936772714443 0.15095640855802680558 1.6587324507724456879" />
<geometry>
<mesh filename="package:///xm430-w350-part-15.stl"/>
</geometry>
<material name="xm430-w350-part-15_material">
<color rgba="0.75294117647058822484 0.75294117647058822484 0.75294117647058822484 1.0"/>
</material>
</visual>
<collision>
<origin xyz="-0.019031716180273727107 0.040045794422456669481 -0.051969617817816123051" rpy="-1.0405433936772714443 0.15095640855802680558 1.6587324507724456879" />
<geometry>
<mesh filename="package:///xm430-w350-part-15.stl"/>
</geometry>
</collision>
<visual>
<origin xyz="-0.024322307906781324982 0.026275538443885554374 -0.061133191490231088283" rpy="-7.038361752181275163e-18 -1.0471975511965980754 5.1698788284564264118e-26" />
<geometry>
<mesh filename="package:///xm430-w350-part-16.stl"/>
</geometry>
<material name="xm430-w350-part-16_material">
<color rgba="0.25098039215686274161 0.25098039215686274161 0.25098039215686274161 1.0"/>
</material>
</visual>
<collision>
<origin xyz="-0.024322307906781324982 0.026275538443885554374 -0.061133191490231088283" rpy="-7.038361752181275163e-18 -1.0471975511965980754 5.1698788284564264118e-26" />
<geometry>
<mesh filename="package:///xm430-w350-part-16.stl"/>
</geometry>
</collision>
<visual>
<origin xyz="-0.024322307906781324982 0.026275538443885554374 -0.061133191490231088283" rpy="-7.038361752181275163e-18 -1.0471975511965980754 5.1698788284564264118e-26" />
<geometry>
<mesh filename="package:///xm430-w350-part-6.stl"/>
</geometry>
<material name="xm430-w350-part-6_material">
<color rgba="0.25098039215686274161 0.25098039215686274161 0.25098039215686274161 1.0"/>
</material>
</visual>
<collision>
<origin xyz="-0.024322307906781324982 0.026275538443885554374 -0.061133191490231088283" rpy="-7.038361752181275163e-18 -1.0471975511965980754 5.1698788284564264118e-26" />
<geometry>
<mesh filename="package:///xm430-w350-part-6.stl"/>
</geometry>
</collision>
<visual>
<origin xyz="-0.018165690776489124697 0.040045794422456669481 -0.052469617817816192884" rpy="-1.0405433936772721104 0.15095640855802730518 1.6587324507724454659" />
<geometry>
<mesh filename="package:///xm430-w350-part-1.stl"/>
</geometry>
<material name="xm430-w350-part-1_material">
<color rgba="0.75294117647058822484 0.75294117647058822484 0.75294117647058822484 1.0"/>
</material>
</visual>
<collision>
<origin xyz="-0.018165690776489124697 0.040045794422456669481 -0.052469617817816192884" rpy="-1.0405433936772721104 0.15095640855802730518 1.6587324507724454659" />
<geometry>
<mesh filename="package:///xm430-w350-part-1.stl"/>
</geometry>
</collision>
<inertial>
<origin xyz="0.0060703706510037572577 -0.037699325943363948266 -0.010094662504829907818" rpy="0 0 0"/>
<mass value="2.6377530287495676298" />
<inertia ixx="0.0043433505749483755295" ixy="-4.5361561547795793269e-06"  ixz="-1.5332484975583938135e-10" iyy="0.0029528640597614968892" iyz="6.2072406522814852717e-10" izz="0.0043293030138522080666" />
</inertial>
</link>

<link name="finger_assembly_-_main">
<visual>
<origin xyz="0.050000000000254334054 -0.071998460398606897725 0.0040000000005075628251" rpy="-6.93889390390712977e-17 5.5511151231257087464e-16 -1.5707963267948987784" />
<geometry>
<mesh filename="package:///l1.stl"/>
</geometry>
<material name="l1_material">
<color rgba="0.30196078431372547213 0.30196078431372547213 0.30196078431372547213 1.0"/>
</material>
</visual>
<collision>
<origin xyz="0.050000000000254334054 -0.071998460398606897725 0.0040000000005075628251" rpy="-6.93889390390712977e-17 5.5511151231257087464e-16 -1.5707963267948987784" />
<geometry>
<mesh filename="package:///l1.stl"/>
</geometry>
</collision>
<visual>
<origin xyz="0.050000000000254278543 -0.07199846039860662017 0.0040000000005075767029" rpy="-6.9388939039071371656e-17 6.1062266354382820862e-16 -1.5707963267948990005" />
<geometry>
<mesh filename="package:///l2.stl"/>
</geometry>
<material name="l2_material">
<color rgba="0.30196078431372547213 0.30196078431372547213 0.30196078431372547213 1.0"/>
</material>
</visual>
<collision>
<origin xyz="0.050000000000254278543 -0.07199846039860662017 0.0040000000005075767029" rpy="-6.9388939039071371656e-17 6.1062266354382820862e-16 -1.5707963267948990005" />
<geometry>
<mesh filename="package:///l2.stl"/>
</geometry>
</collision>
<visual>
<origin xyz="0.050000000000254320176 -0.071998460398606717314 0.0040000000005075420084" rpy="2.6367796834847117778e-16 4.996003610813140337e-16 -1.5707963267948987784" />
<geometry>
<mesh filename="package:///tip_shoulder_screw.stl"/>
</geometry>
<material name="tip_shoulder_screw_material">
<color rgba="0.75294117647058822484 0.75294117647058822484 0.75294117647058822484 1.0"/>
</material>
</visual>
<collision>
<origin xyz="0.050000000000254320176 -0.071998460398606717314 0.0040000000005075420084" rpy="2.6367796834847117778e-16 4.996003610813140337e-16 -1.5707963267948987784" />
<geometry>
<mesh filename="package:///tip_shoulder_screw.stl"/>
</geometry>
</collision>
<visual>
<origin xyz="0.049800000000254314447 -0.07226215247837883271 0.004000000000507569764" rpy="-6.93889390390712977e-17 4.9960036108131393509e-16 -1.5707963267948987784" />
<geometry>
<mesh filename="package:///finger_backbone.stl"/>
</geometry>
<material name="finger_backbone_material">
<color rgba="0.45098039215686275272 0.43529411764705883137 0.43529411764705883137 1.0"/>
</material>
</visual>
<collision>
<origin xyz="0.049800000000254314447 -0.07226215247837883271 0.004000000000507569764" rpy="-6.93889390390712977e-17 4.9960036108131393509e-16 -1.5707963267948987784" />
<geometry>
<mesh filename="package:///finger_backbone.stl"/>
</geometry>
</collision>
<visual>
<origin xyz="0 0 0.019000000000254004678" rpy="-1.570796326794896558 -1.570796326794896558 0" />
<geometry>
<mesh filename="package:///fr12_h101.stl"/>
</geometry>
<material name="fr12_h101_material">
<color rgba="0 0 0 1.0"/>
</material>
</visual>
<collision>
<origin xyz="0 0 0.019000000000254004678" rpy="-1.570796326794896558 -1.570796326794896558 0" />
<geometry>
<mesh filename="package:///fr12_h101.stl"/>
</geometry>
</collision>
<inertial>
<origin xyz="0.063076780520135544705 -0.018482153655559423883 0.018993451551953085404" rpy="0 0 0"/>
<mass value="0.034646995418150625112" />
<inertia ixx="1.3564038042652216851e-05" ixy="8.1758965649479803937e-06"  ixz="1.8413789084247456222e-08" iyy="4.7204471042435543378e-05" iyz="-1.2589418441226132944e-09" izz="5.2636964693385499849e-05" />
</inertial>
</link>

<joint name="finger1" type="revolute">
<origin xyz="-0.0075986708138534309054 0.037599999999999952904 0.05116128391958498639" rpy="-2.101049259912523226 -0.15095640855802808233 1.6587324507724439115" />
<parent link="palm_-_assembly_cross_bar" />
<child link="finger_assembly_-_main" />
<axis xyz="0 0 1"/>
<limit effort="1" velocity="20" />
<joint_properties friction="0.0"/>
</joint>

<link name="finger_assembly_-_main_2">
<visual>
<origin xyz="0.050000000000252384225 -0.071998460398601360488 0.0040000000005082254895" rpy="5.6567454177087514327e-16 3.7996782583512620356e-16 -1.5707963267948896746" />
<geometry>
<mesh filename="package:///l1.stl"/>
</geometry>
<material name="l1_material">
<color rgba="0.30196078431372547213 0.30196078431372547213 0.30196078431372547213 1.0"/>
</material>
</visual>
<collision>
<origin xyz="0.050000000000252384225 -0.071998460398601360488 0.0040000000005082254895" rpy="5.6567454177087514327e-16 3.7996782583512620356e-16 -1.5707963267948896746" />
<geometry>
<mesh filename="package:///l1.stl"/>
</geometry>
</collision>
<visual>
<origin xyz="0.050000000000252425858 -0.071998460398600944155 0.0040000000005082254895" rpy="5.455206464785097521e-16 3.8398658955488723232e-16 -1.5707963267948896746" />
<geometry>
<mesh filename="package:///l2.stl"/>
</geometry>
<material name="l2_material">
<color rgba="0.30196078431372547213 0.30196078431372547213 0.30196078431372547213 1.0"/>
</material>
</visual>
<collision>
<origin xyz="0.050000000000252425858 -0.071998460398600944155 0.0040000000005082254895" rpy="5.455206464785097521e-16 3.8398658955488723232e-16 -1.5707963267948896746" />
<geometry>
<mesh filename="package:///l2.stl"/>
</geometry>
</collision>
<visual>
<origin xyz="0.05000000000025241198 -0.071998460398601166199 0.0040000000005082324284" rpy="5.5676708204342269636e-16 3.8106642178531085468e-16 -1.5707963267948896746" />
<geometry>
<mesh filename="package:///tip_shoulder_screw.stl"/>
</geometry>
<material name="tip_shoulder_screw_material">
<color rgba="0.75294117647058822484 0.75294117647058822484 0.75294117647058822484 1.0"/>
</material>
</visual>
<collision>
<origin xyz="0.05000000000025241198 -0.071998460398601166199 0.0040000000005082324284" rpy="5.5676708204342269636e-16 3.8106642178531085468e-16 -1.5707963267948896746" />
<geometry>
<mesh filename="package:///tip_shoulder_screw.stl"/>
</geometry>
</collision>
<visual>
<origin xyz="0.049800000000252447885 -0.072262152478373226083 0.0040000000005082254895" rpy="5.6562508163730159647e-16 3.7999051779229164491e-16 -1.5707963267948896746" />
<geometry>
<mesh filename="package:///finger_backbone.stl"/>
</geometry>
<material name="finger_backbone_material">
<color rgba="0.45098039215686275272 0.43529411764705883137 0.43529411764705883137 1.0"/>
</material>
</visual>
<collision>
<origin xyz="0.049800000000252447885 -0.072262152478373226083 0.0040000000005082254895" rpy="5.6562508163730159647e-16 3.7999051779229164491e-16 -1.5707963267948896746" />
<geometry>
<mesh filename="package:///finger_backbone.stl"/>
</geometry>
</collision>
<visual>
<origin xyz="6.9388939039072283776e-18 0 0.019000000000254001209" rpy="-1.570796326794896558 -1.570796326794896558 0" />
<geometry>
<mesh filename="package:///fr12_h101.stl"/>
</geometry>
<material name="fr12_h101_material">
<color rgba="0 0 0 1.0"/>
</material>
</visual>
<collision>
<origin xyz="6.9388939039072283776e-18 0 0.019000000000254001209" rpy="-1.570796326794896558 -1.570796326794896558 0" />
<geometry>
<mesh filename="package:///fr12_h101.stl"/>
</geometry>
</collision>
<inertial>
<origin xyz="0.063076780520133324259 -0.018482153655555312588 0.018993451551952970913" rpy="0 0 0"/>
<mass value="0.034646995418150625112" />
<inertia ixx="1.3564038042650305944e-05" ixy="8.1758965649455578794e-06"  ixz="1.841378908434440179e-08" iyy="4.7204471042433049713e-05" iyz="-1.2589418440488403643e-09" izz="5.26369646933788049e-05" />
</inertial>
</link>

<joint name="finger2" type="revolute">
<origin xyz="0.065590767428789401028 0.037600000000000022293 -0.029094657951643378146" rpy="-1.0893877507624841069e-15 8.5643825082213672332e-16 1.3962634016856947383" />
<parent link="palm_-_assembly_cross_bar" />
<child link="finger_assembly_-_main_2" />
<axis xyz="0 0 1"/>
<limit effort="1" velocity="20" />
<joint_properties friction="0.0"/>
</joint>

<link name="finger_assembly_-_main_3">
<visual>
<origin xyz="0.050000000000256512867 -0.071998460398608271626 0.0040000000005079514032" rpy="4.8572257327350588783e-16 -1.1601830607332882692e-14 -1.5707963267948972241" />
<geometry>
<mesh filename="package:///l1.stl"/>
</geometry>
<material name="l1_material">
<color rgba="0.30196078431372547213 0.30196078431372547213 0.30196078431372547213 1.0"/>
</material>
</visual>
<collision>
<origin xyz="0.050000000000256512867 -0.071998460398608271626 0.0040000000005079514032" rpy="4.8572257327350588783e-16 -1.1601830607332882692e-14 -1.5707963267948972241" />
<geometry>
<mesh filename="package:///l1.stl"/>
</geometry>
</collision>
<visual>
<origin xyz="0.050000000000256512867 -0.071998460398607577737 0.0040000000005079930365" rpy="-1.1102230246251285359e-15 -6.6058269965194731562e-15 -1.5707963267948954478" />
<geometry>
<mesh filename="package:///l2.stl"/>
</geometry>
<material name="l2_material">
<color rgba="0.30196078431372547213 0.30196078431372547213 0.30196078431372547213 1.0"/>
</material>
</visual>
<collision>
<origin xyz="0.050000000000256512867 -0.071998460398607577737 0.0040000000005079930365" rpy="-1.1102230246251285359e-15 -6.6058269965194731562e-15 -1.5707963267948954478" />
<geometry>
<mesh filename="package:///l2.stl"/>
</geometry>
</collision>
<visual>
<origin xyz="0.050000000000256540622 -0.071998460398608132849 0.0040000000005079167087" rpy="6.1062266354383609723e-16 -1.1490808304870370193e-14 -1.5707963267948981123" />
<geometry>
<mesh filename="package:///tip_shoulder_screw.stl"/>
</geometry>
<material name="tip_shoulder_screw_material">
<color rgba="0.75294117647058822484 0.75294117647058822484 0.75294117647058822484 1.0"/>
</material>
</visual>
<collision>
<origin xyz="0.050000000000256540622 -0.071998460398608132849 0.0040000000005079167087" rpy="6.1062266354383609723e-16 -1.1490808304870370193e-14 -1.5707963267948981123" />
<geometry>
<mesh filename="package:///tip_shoulder_screw.stl"/>
</geometry>
</collision>
<visual>
<origin xyz="0.049800000000256562649 -0.072262152478380303755 0.0040000000005079167087" rpy="5.551115123125781716e-16 -1.1601830607332882692e-14 -1.5707963267948976682" />
<geometry>
<mesh filename="package:///finger_backbone.stl"/>
</geometry>
<material name="finger_backbone_material">
<color rgba="0.45098039215686275272 0.43529411764705883137 0.43529411764705883137 1.0"/>
</material>
</visual>
<collision>
<origin xyz="0.049800000000256562649 -0.072262152478380303755 0.0040000000005079167087" rpy="5.551115123125781716e-16 -1.1601830607332882692e-14 -1.5707963267948976682" />
<geometry>
<mesh filename="package:///finger_backbone.stl"/>
</geometry>
</collision>
<visual>
<origin xyz="-6.9388939039072283776e-18 -6.9388939039072283776e-18 0.019000000000254004678" rpy="-1.570796326794896558 -1.570796326794896558 0" />
<geometry>
<mesh filename="package:///fr12_h101.stl"/>
</geometry>
<material name="fr12_h101_material">
<color rgba="0 0 0 1.0"/>
</material>
</visual>
<collision>
<origin xyz="-6.9388939039072283776e-18 -6.9388939039072283776e-18 0.019000000000254004678" rpy="-1.570796326794896558 -1.570796326794896558 0" />
<geometry>
<mesh filename="package:///fr12_h101.stl"/>
</geometry>
</collision>
<inertial>
<origin xyz="0.063076780520136807584 -0.018482153655560856764 0.018993451551952748868" rpy="0 0 0"/>
<mass value="0.034646995418150625112" />
<inertia ixx="1.3564038042652443855e-05" ixy="8.1758965649488325088e-06"  ixz="1.8413789084397619282e-08" iyy="4.7204471042436017716e-05" iyz="-1.2589418441080100411e-09" izz="5.2636964693386346882e-05" />
</inertial>
</link>

<joint name="finger3" type="revolute">
<origin xyz="-0.040507636157662112175 0.037600000000000001477 -0.052350599822869277322" rpy="2.101049259912523226 0.15095640855803008074 1.6587324507724459099" />
<parent link="palm_-_assembly_cross_bar" />
<child link="finger_assembly_-_main_3" />
<axis xyz="0 0 1"/>
<limit effort="1" velocity="20" />
<joint_properties friction="0.0"/>
</joint>


</robot>
