<?xml version="1.0" ?>
<mujoco>
  <worldbody>
    <body name="falling_ball" pos="70 90 150" gravcomp="1">
      <geom type="sphere" size="30" rgba="0.2 0.2 0.8 1" density="10"/>
      <joint type="slide" axis="1 0 0" name="ball_slide_x"/>
      <joint type="slide" axis="0 1 0" name="ball_slide_y"/>
      <joint type="slide" axis="0 0 1" name="ball_slide_z"/>
      <site name="ball_site" pos="0 0 0" size="1" rgba="1 0 0 1"/>
    </body>
    <body name="base_box" pos="60 4.77 60.877">
      <geom type="box" size="60 4.77 60.877" rgba="0.6 0.6 0.6 1" density="1"/>
      <body name="small_box_1" pos="0 5.6 60" euler="-15.642 0 0">
        <geom type="box" size="60 0.6 1" rgba="0.8 0.3 0.3 1"/>
        <joint type="hinge" name="joint_0" axis="1 0 0" pos="0 0 0" range="-90 90" stiffness="50000" damping="50000" springref="0"/>
        <body name="block_2" pos="0 14.0 0">
          <geom type="box" size="60 6.0 1" rgba="0.8 0.2 0.2 1" density="1000"/>
          <site name="site2" pos="0 0 0" size="3" rgba="1 0 0 1"/>
          <joint type="hinge" name="joint_2" axis="1 0 0" range="-180 180" pos="0 0 0" stiffness="50000" damping="50000" springref="0" actuatorfrclimited="false"/>
          <body name="block_3" pos="0 14.0 0">
            <geom type="box" size="60 6.0 1" rgba="0.8 0.2 0.2 1" density="1000"/>
            <site name="site3" pos="0 0 0" size="3" rgba="1 0 0 1"/>
            <joint type="hinge" name="joint_3" axis="1 0 0" range="-180 180" pos="0 0 0" stiffness="50000" damping="50000" springref="0" actuatorfrclimited="false"/>
            <body name="lbox_6" pos="0 3.0 -27.7" euler="15.642 0 0">
              <geom type="box" size="60 1 21.7" rgba="0.8 0.3 0.3 1"/>
              <joint type="hinge" name="joint_6" axis="1 0 0" pos="0 0 0" range="-180 180" stiffness="50000" damping="50000" springref="0"/>
            </body>
            <body name="block_8" pos="0 14.0 0">
              <geom type="box" size="60 6.0 1" rgba="0.8 0.2 0.2 1" density="1000"/>
              <site name="site8" pos="0 0 0" size="3" rgba="1 0 0 1"/>
              <joint type="hinge" name="joint_8" axis="1 0 0" range="-180 180" pos="0 0 0" stiffness="50000" damping="50000" springref="0" actuatorfrclimited="false"/>
              <body name="block_9" pos="0 14.0 0">
                <geom type="box" size="60 6.0 1" rgba="0.8 0.2 0.2 1" density="1000"/>
                <site name="site9" pos="0 0 0" size="3" rgba="1 0 0 1"/>
                <joint type="hinge" name="joint_9" axis="1 0 0" range="-180 180" pos="0 0 0" stiffness="50000" damping="50000" springref="0" actuatorfrclimited="false"/>
                <body name="lbox_12" pos="0 3.0 -23.7" euler="15.642 0 0">
                  <geom type="box" size="60 1 17.7" rgba="0.8 0.3 0.3 1"/>
                  <joint type="hinge" name="joint_12" axis="1 0 0" pos="0 0 0" range="-180 180" stiffness="50000" damping="50000" springref="0"/>
                </body>
                <body name="block_14" pos="0 14.0 0">
                  <geom type="box" size="60 6.0 1" rgba="0.8 0.2 0.2 1" density="1000"/>
                  <site name="site14" pos="0 0 0" size="3" rgba="1 0 0 1"/>
                  <joint type="hinge" name="joint_14" axis="1 0 0" range="-180 180" pos="0 0 0" stiffness="50000" damping="50000" springref="0" actuatorfrclimited="false"/>
                  <body name="block_15" pos="0 14.0 0">
                    <geom type="box" size="60 6.0 1" rgba="0.8 0.2 0.2 1" density="1000"/>
                    <site name="site15" pos="0 0 0" size="3" rgba="1 0 0 1"/>
                    <joint type="hinge" name="joint_15" axis="1 0 0" range="-180 180" pos="0 0 0" stiffness="50000" damping="50000" springref="0" actuatorfrclimited="false"/>
                    <body name="lbox_18" pos="0 3.0 -20" euler="15.642 0 0">
                      <geom type="box" size="60 1 14" rgba="0.8 0.3 0.3 1"/>
                      <joint type="hinge" name="joint_18" axis="1 0 0" pos="0 0 0" range="-180 180" stiffness="50000" damping="50000" springref="0"/>
                    </body>
                    <body name="block_20" pos="0 14.0 0">
                      <geom type="box" size="60 6.0 1" rgba="0.8 0.2 0.2 1" density="1000"/>
                      <site name="site20" pos="0 0 0" size="3" rgba="1 0 0 1"/>
                      <joint type="hinge" name="joint_20" axis="1 0 0" range="-180 180" pos="0 0 0" stiffness="50000" damping="50000" springref="0" actuatorfrclimited="false"/>
                      <body name="block_21" pos="0 14.0 0">
                        <geom type="box" size="60 6.0 1" rgba="0.8 0.2 0.2 1" density="1000"/>
                        <site name="site21" pos="0 0 0" size="3" rgba="1 0 0 1"/>
                        <joint type="hinge" name="joint_21" axis="1 0 0" range="-180 180" pos="0 0 0" stiffness="50000" damping="50000" springref="0" actuatorfrclimited="false"/>
                        <body name="lbox_24" pos="0 3.0 -16" euler="15.642 0 0">
                          <geom type="box" size="60 1 10" rgba="0.8 0.3 0.3 1"/>
                          <joint type="hinge" name="joint_24" axis="1 0 0" pos="0 0 0" range="-180 180" stiffness="50000" damping="50000" springref="0"/>
                        </body>
                        <body name="block_26" pos="0 14.0 0">
                          <geom type="box" size="60 6.0 1" rgba="0.8 0.2 0.2 1" density="1000"/>
                          <site name="site26" pos="0 0 0" size="3" rgba="1 0 0 1"/>
                          <joint type="hinge" name="joint_26" axis="1 0 0" range="-180 180" pos="0 0 0" stiffness="50000" damping="50000" springref="0" actuatorfrclimited="false"/>
                          <body name="block_27" pos="0 14.0 0">
                            <geom type="box" size="60 6.0 1" rgba="0.8 0.2 0.2 1" density="1000"/>
                            <site name="site27" pos="0 0 0" size="3" rgba="1 0 0 1"/>
                            <joint type="hinge" name="joint_27" axis="1 0 0" range="-180 180" pos="0 0 0" stiffness="50000" damping="50000" springref="0" actuatorfrclimited="false"/>
                            <body name="lbox_30" pos="0 3.0 -12.3" euler="15.642 0 0">
                              <geom type="box" size="60 1 6.3" rgba="0.8 0.3 0.3 1"/>
                              <joint type="hinge" name="joint_30" axis="1 0 0" pos="0 0 0" range="-180 180" stiffness="50000" damping="50000" springref="0"/>
                            </body>
                            <body name="block_32" pos="0 14.0 0">
                              <geom type="box" size="60 6.0 1" rgba="0.8 0.2 0.2 1" density="1000"/>
                              <site name="site32" pos="0 0 0" size="3" rgba="1 0 0 1"/>
                              <joint type="hinge" name="joint_32" axis="1 0 0" range="-180 180" pos="0 0 0" stiffness="50000" damping="50000" springref="0" actuatorfrclimited="false"/>
                              <body name="block_33" pos="0 14.0 0">
                                <geom type="box" size="60 6.0 1" rgba="0.8 0.2 0.2 1" density="1000"/>
                                <site name="site33" pos="0 0 0" size="3" rgba="1 0 0 1"/>
                                <joint type="hinge" name="joint_33" axis="1 0 0" range="-180 180" pos="0 0 0" stiffness="50000" damping="50000" springref="0" actuatorfrclimited="false"/>
                                <body name="lbox_36" pos="0 3.0 -8.5" euler="15.642 0 0">
                                  <geom type="box" size="60 1 2.5" rgba="0.8 0.3 0.3 1"/>
                                  <joint type="hinge" name="joint_36" axis="1 0 0" pos="0 0 0" range="-180 180" stiffness="50000" damping="50000" springref="0"/>
                                </body>
                              </body>
                            </body>
                          </body>
                        </body>
                      </body>
                    </body>
                  </body>
                </body>
              </body>
            </body>
          </body>
        </body>
      </body>
      <body name="small_box_2" pos="0 5.6 -60" euler="15.642 0 0">
        <geom type="box" size="60 0.6 1" rgba="0.3 0.8 0.3 1"/>
        <joint type="hinge" name="joint_1" axis="1 0 0" pos="0 0 0" range="-90 90" stiffness="50000" damping="50000" springref="0"/>
        <body name="block_4" pos="0 14.0 0">
          <geom type="box" size="60 6.0 1" rgba="0.8 0.2 0.2 1" density="1000"/>
          <site name="site4" pos="0 0 0" size="3" rgba="1 0 0 1"/>
          <joint type="hinge" name="joint_4" axis="1 0 0" range="-180 180" pos="0 0 0" stiffness="50000" damping="50000" springref="0" actuatorfrclimited="false"/>
          <body name="block_5" pos="0 14.0 0">
            <geom type="box" size="60 6.0 1" rgba="0.8 0.2 0.2 1" density="1000"/>
            <site name="site5" pos="0 0 0" size="3" rgba="1 0 0 1"/>
            <joint type="hinge" name="joint_5" axis="1 0 0" range="-180 180" pos="0 0 0" stiffness="50000" damping="50000" springref="0" actuatorfrclimited="false"/>
            <body name="rbox_7" pos="0 3.0 27.7" euler="-15.642 0 0">
              <geom type="box" size="60 1 21.7" rgba="0.3 0.8 0.3 1"/>
              <joint type="hinge" name="joint_7" axis="1 0 0" pos="0 0 0" range="-180 180" stiffness="50000" damping="50000" springref="0"/>
            </body>
            <body name="block_10" pos="0 14.0 0">
              <geom type="box" size="60 6.0 1" rgba="0.8 0.2 0.2 1" density="1000"/>
              <site name="site10" pos="0 0 0" size="3" rgba="1 0 0 1"/>
              <joint type="hinge" name="joint_10" axis="1 0 0" range="-180 180" pos="0 0 0" stiffness="50000" damping="50000" springref="0" actuatorfrclimited="false"/>
              <body name="block_11" pos="0 14.0 0">
                <geom type="box" size="60 6.0 1" rgba="0.8 0.2 0.2 1" density="1000"/>
                <site name="site11" pos="0 0 0" size="3" rgba="1 0 0 1"/>
                <joint type="hinge" name="joint_11" axis="1 0 0" range="-180 180" pos="0 0 0" stiffness="50000" damping="50000" springref="0" actuatorfrclimited="false"/>
                <body name="rbox_13" pos="0 3.0 23.7" euler="-15.642 0 0">
                  <geom type="box" size="60 1 17.7" rgba="0.3 0.8 0.3 1"/>
                  <joint type="hinge" name="joint_13" axis="1 0 0" pos="0 0 0" range="-180 180" stiffness="50000" damping="50000" springref="0"/>
                </body>
                <body name="block_16" pos="0 14.0 0">
                  <geom type="box" size="60 6.0 1" rgba="0.8 0.2 0.2 1" density="1000"/>
                  <site name="site16" pos="0 0 0" size="3" rgba="1 0 0 1"/>
                  <joint type="hinge" name="joint_16" axis="1 0 0" range="-180 180" pos="0 0 0" stiffness="50000" damping="50000" springref="0" actuatorfrclimited="false"/>
                  <body name="block_17" pos="0 14.0 0">
                    <geom type="box" size="60 6.0 1" rgba="0.8 0.2 0.2 1" density="1000"/>
                    <site name="site17" pos="0 0 0" size="3" rgba="1 0 0 1"/>
                    <joint type="hinge" name="joint_17" axis="1 0 0" range="-180 180" pos="0 0 0" stiffness="50000" damping="50000" springref="0" actuatorfrclimited="false"/>
                    <body name="rbox_19" pos="0 3.0 20" euler="-15.642 0 0">
                      <geom type="box" size="60 1 14" rgba="0.3 0.8 0.3 1"/>
                      <joint type="hinge" name="joint_19" axis="1 0 0" pos="0 0 0" range="-180 180" stiffness="50000" damping="50000" springref="0"/>
                    </body>
                    <body name="block_22" pos="0 14.0 0">
                      <geom type="box" size="60 6.0 1" rgba="0.8 0.2 0.2 1" density="1000"/>
                      <site name="site22" pos="0 0 0" size="3" rgba="1 0 0 1"/>
                      <joint type="hinge" name="joint_22" axis="1 0 0" range="-180 180" pos="0 0 0" stiffness="50000" damping="50000" springref="0" actuatorfrclimited="false"/>
                      <body name="block_23" pos="0 14.0 0">
                        <geom type="box" size="60 6.0 1" rgba="0.8 0.2 0.2 1" density="1000"/>
                        <site name="site23" pos="0 0 0" size="3" rgba="1 0 0 1"/>
                        <joint type="hinge" name="joint_23" axis="1 0 0" range="-180 180" pos="0 0 0" stiffness="50000" damping="50000" springref="0" actuatorfrclimited="false"/>
                        <body name="rbox_25" pos="0 3.0 16" euler="-15.642 0 0">
                          <geom type="box" size="60 1 10" rgba="0.3 0.8 0.3 1"/>
                          <joint type="hinge" name="joint_25" axis="1 0 0" pos="0 0 0" range="-180 180" stiffness="50000" damping="50000" springref="0"/>
                        </body>
                        <body name="block_28" pos="0 14.0 0">
                          <geom type="box" size="60 6.0 1" rgba="0.8 0.2 0.2 1" density="1000"/>
                          <site name="site28" pos="0 0 0" size="3" rgba="1 0 0 1"/>
                          <joint type="hinge" name="joint_28" axis="1 0 0" range="-180 180" pos="0 0 0" stiffness="50000" damping="50000" springref="0" actuatorfrclimited="false"/>
                          <body name="block_29" pos="0 14.0 0">
                            <geom type="box" size="60 6.0 1" rgba="0.8 0.2 0.2 1" density="1000"/>
                            <site name="site29" pos="0 0 0" size="3" rgba="1 0 0 1"/>
                            <joint type="hinge" name="joint_29" axis="1 0 0" range="-180 180" pos="0 0 0" stiffness="50000" damping="50000" springref="0" actuatorfrclimited="false"/>
                            <body name="rbox_31" pos="0 3.0 12.3" euler="-15.642 0 0">
                              <geom type="box" size="60 1 6.3" rgba="0.3 0.8 0.3 1"/>
                              <joint type="hinge" name="joint_31" axis="1 0 0" pos="0 0 0" range="-180 180" stiffness="50000" damping="50000" springref="0"/>
                            </body>
                            <body name="block_34" pos="0 14.0 0">
                              <geom type="box" size="60 6.0 1" rgba="0.8 0.2 0.2 1" density="1000"/>
                              <site name="site34" pos="0 0 0" size="3" rgba="1 0 0 1"/>
                              <joint type="hinge" name="joint_34" axis="1 0 0" range="-180 180" pos="0 0 0" stiffness="50000" damping="50000" springref="0" actuatorfrclimited="false"/>
                              <body name="block_35" pos="0 14.0 0">
                                <geom type="box" size="60 6.0 1" rgba="0.8 0.2 0.2 1" density="1000"/>
                                <site name="site35" pos="0 0 0" size="3" rgba="1 0 0 1"/>
                                <joint type="hinge" name="joint_35" axis="1 0 0" range="-180 180" pos="0 0 0" stiffness="50000" damping="50000" springref="0" actuatorfrclimited="false"/>
                                <body name="rbox_37" pos="0 3.0 8.5" euler="-15.642 0 0">
                                  <geom type="box" size="60 1 2.5" rgba="0.3 0.8 0.3 1"/>
                                  <joint type="hinge" name="joint_37" axis="1 0 0" pos="0 0 0" range="-180 180" stiffness="50000" damping="50000" springref="0"/>
                                </body>
                              </body>
                            </body>
                          </body>
                        </body>
                      </body>
                    </body>
                  </body>
                </body>
              </body>
            </body>
          </body>
        </body>
      </body>
    </body>
  </worldbody>
  <option integrator="implicitfast"/>
  <equality>
    <weld body1="lbox_6" body2="rbox_7" active="true" solref="0.02 1" solimp="0.9 0.95 0.001"/>
  </equality>
  <equality>
    <weld body1="lbox_12" body2="rbox_13" active="true" solref="0.02 1" solimp="0.9 0.95 0.001"/>
  </equality>
  <equality>
    <weld body1="lbox_18" body2="rbox_19" active="true" solref="0.02 1" solimp="0.9 0.95 0.001"/>
  </equality>
  <equality>
    <weld body1="lbox_24" body2="rbox_25" active="true" solref="0.02 1" solimp="0.9 0.95 0.001"/>
  </equality>
  <equality>
    <weld body1="lbox_30" body2="rbox_31" active="true" solref="0.02 1" solimp="0.9 0.95 0.001"/>
  </equality>
  <equality>
    <weld body1="lbox_36" body2="rbox_37" active="true" solref="0.02 1" solimp="0.9 0.95 0.001"/>
  </equality>
  <actuator>
    <position joint="joint_0" ctrlrange="-1 1" gear="100" kp="99999990" kv="9999999"/>
    <position joint="joint_1" ctrlrange="-1 1" gear="100" kp="99999990" kv="9999999"/>
    <position joint="joint_2" ctrlrange="-1 1" gear="100" kp="99999990" kv="9999999"/>
    <position joint="joint_3" ctrlrange="-1 1" gear="100" kp="99999990" kv="9999999"/>
    <position joint="joint_4" ctrlrange="-1 1" gear="100" kp="99999990" kv="9999999"/>
    <position joint="joint_5" ctrlrange="-1 1" gear="100" kp="99999990" kv="9999999"/>
    <position joint="joint_6" ctrlrange="-1 1" gear="100" kp="99999990" kv="9999999"/>
    <position joint="joint_7" ctrlrange="-1 1" gear="100" kp="99999990" kv="9999999"/>
    <position joint="joint_8" ctrlrange="-1 1" gear="100" kp="99999990" kv="9999999"/>
    <position joint="joint_9" ctrlrange="-1 1" gear="100" kp="99999990" kv="9999999"/>
    <position joint="joint_10" ctrlrange="-1 1" gear="100" kp="99999990" kv="9999999"/>
    <position joint="joint_11" ctrlrange="-1 1" gear="100" kp="99999990" kv="9999999"/>
    <position joint="joint_12" ctrlrange="-1 1" gear="100" kp="99999990" kv="9999999"/>
    <position joint="joint_13" ctrlrange="-1 1" gear="100" kp="99999990" kv="9999999"/>
    <position joint="joint_14" ctrlrange="-1 1" gear="100" kp="99999990" kv="9999999"/>
    <position joint="joint_15" ctrlrange="-1 1" gear="100" kp="99999990" kv="9999999"/>
    <position joint="joint_16" ctrlrange="-1 1" gear="100" kp="99999990" kv="9999999"/>
    <position joint="joint_17" ctrlrange="-1 1" gear="100" kp="99999990" kv="9999999"/>
    <position joint="joint_18" ctrlrange="-1 1" gear="100" kp="99999990" kv="9999999"/>
    <position joint="joint_19" ctrlrange="-1 1" gear="100" kp="99999990" kv="9999999"/>
    <position joint="joint_20" ctrlrange="-1 1" gear="100" kp="99999990" kv="9999999"/>
    <position joint="joint_21" ctrlrange="-1 1" gear="100" kp="99999990" kv="9999999"/>
    <position joint="joint_22" ctrlrange="-1 1" gear="100" kp="99999990" kv="9999999"/>
    <position joint="joint_23" ctrlrange="-1 1" gear="100" kp="99999990" kv="9999999"/>
    <position joint="joint_24" ctrlrange="-1 1" gear="100" kp="99999990" kv="9999999"/>
    <position joint="joint_25" ctrlrange="-1 1" gear="100" kp="99999990" kv="9999999"/>
    <position joint="joint_26" ctrlrange="-1 1" gear="100" kp="99999990" kv="9999999"/>
    <position joint="joint_27" ctrlrange="-1 1" gear="100" kp="99999990" kv="9999999"/>
    <position joint="joint_28" ctrlrange="-1 1" gear="100" kp="99999990" kv="9999999"/>
    <position joint="joint_29" ctrlrange="-1 1" gear="100" kp="99999990" kv="9999999"/>
    <position joint="joint_30" ctrlrange="-1 1" gear="100" kp="99999990" kv="9999999"/>
    <position joint="joint_31" ctrlrange="-1 1" gear="100" kp="99999990" kv="9999999"/>
    <position joint="joint_32" ctrlrange="-1 1" gear="100" kp="99999990" kv="9999999"/>
    <position joint="joint_33" ctrlrange="-1 1" gear="100" kp="99999990" kv="9999999"/>
    <position joint="joint_34" ctrlrange="-1 1" gear="100" kp="99999990" kv="9999999"/>
    <position joint="joint_35" ctrlrange="-1 1" gear="100" kp="99999990" kv="9999999"/>
    <position joint="joint_36" ctrlrange="-1 1" gear="100" kp="99999990" kv="9999999"/>
    <position joint="joint_37" ctrlrange="-1 1" gear="100" kp="99999990" kv="9999999"/>
    <position joint="ball_slide_x" ctrllimited="true" ctrlrange="-70000 70000" kp="10000" dampratio="1" gear="100" name="ball_motor_x"/>
    <position joint="ball_slide_y" ctrllimited="true" ctrlrange="-70000 70000" kp="10000" dampratio="1" gear="100" name="ball_motor_y"/>
    <position joint="ball_slide_z" ctrllimited="true" ctrlrange="-70000 70000" kp="10000" dampratio="1" gear="100" name="ball_motor_z"/>
  </actuator>
</mujoco>
