<mujoco model="onshape">
  <compiler angle="radian" />
  <asset>
    <mesh name="m3_heat_set_insert" file="m3_heat_set_insert.stl" scale="10 10 10"/>
    <mesh name="ur5_adaptor" file="ur5_adaptor.stl" scale="10 10 10"/>
    <mesh name="ur5_arm_adapter" file="ur5_arm_adapter.stl" scale="10 10 10"/>
    <mesh name="palm_lower" file="palm_lower.stl" scale="10 10 10"/>
    <mesh name="part_1" file="part_1.stl" scale="10 10 10"/>
    <mesh name="palm_base" file="palm_base.stl" scale="10 10 10"/>
    <mesh name="palm_upper" file="palm_upper.stl" scale="10 10 10"/>
    <mesh name="xm430-w350-part-4" file="xm430-w350-part-4.stl" scale="10 10 10"/>
    <mesh name="xm430-w350-part-15" file="xm430-w350-part-15.stl" scale="10 10 10"/>
    <mesh name="xm430-w350-part-16" file="xm430-w350-part-16.stl" scale="10 10 10"/>
    <mesh name="xm430-w350-part-6" file="xm430-w350-part-6.stl" scale="10 10 10"/>
    <mesh name="xm430-w350-part-1" file="xm430-w350-part-1.stl" scale="10 10 10"/>
    <mesh name="l1" file="l1.stl" scale="10 10 10"/>
    <mesh name="l2" file="l2.stl" scale="10 10 10"/>
    <mesh name="tip_shoulder_screw" file="tip_shoulder_screw.stl" scale="10 10 10"/>
    <mesh name="finger_backbone" file="finger_backbone.stl" scale="10 10 10"/>
    <mesh name="fr12_h101" file="fr12_h101.stl" scale="10 10 10"/>
  </asset>
  
  <asset>
    <texture name="grid" type="2d" builtin="checker" rgb1=".1 .2 .3" rgb2=".2 .3 .4" width="300" height="300" mark="edge" markrgb=".2 .3 .4" />
    <material name="grid" texture="grid" texrepeat="2 2" texuniform="true" reflectance=".2" />
  </asset>
  <option solver="CG" tolerance="1e-6" timestep=".0005" integrator="implicitfast" />

  <extension>
    <plugin plugin="mujoco.elasticity.solid" />
  </extension>
  <worldbody>
    <geom name="ground" type="plane" pos="0.0 0.0 -5.0" size="2 2 .1" material="grid" solimp=".99 .99 .01" solref=".001 1" />
    <geom pos="-0.0513595 -0.213 -0.100947" quat="0 0 -0.707107 -0.707107" type="mesh" rgba="1 0.756863 0.054902 1" mesh="m3_heat_set_insert" />
    <geom pos="0.0582815 0.005999999999999999 -0.100947" quat="0 0 -0.707107 -0.707107" type="mesh" rgba="0.45098 0.435294 0.435294 1" mesh="ur5_adaptor" />
    <geom pos="-0.270718 -0.65194 -0.100947" quat="0 0.707107 0 -0.707107" type="mesh" rgba="0.498039 0.498039 0.498039 1" mesh="ur5_arm_adapter" />
    <geom pos="0.0582815 0.005999999999999999 -0.100947" quat="0 0 0.707107 0.707107" type="mesh" rgba="0.301961 0.301961 0.301961 1" mesh="palm_lower" />
    <geom pos="0.113102 0.0 -0.0059946700000000006" quat="0 0.258819 0 -0.965926" type="mesh" rgba="0.752941 0.752941 0.752941 1" mesh="part_1" />
    <geom pos="0.0582815 0.005999999999999999 -0.100947" quat="0 0 -0.707107 -0.707107" type="mesh" rgba="0.45098 0.435294 0.435294 1" mesh="palm_base" />
    <geom pos="0.0582815 0.005999999999999999 -0.100947" quat="0.612372 -0.612372 0.353553 0.353553" type="mesh" rgba="0.301961 0.301961 0.301961 1" mesh="palm_upper" />
    <geom pos="-0.0513595 0.0 -0.100947" quat="0 0.258819 0 -0.965926" type="mesh" rgba="0.752941 0.752941 0.752941 1" mesh="part_1" />
    <geom pos="0.113102 0.0 -0.19589800000000002" quat="0 0.258819 0 -0.965926" type="mesh" rgba="0.752941 0.752941 0.752941 1" mesh="part_1" />
    <geom pos="0.651041 0.262755 -0.106865" quat="0 0 1 0" type="mesh" rgba="0.25098 0.25098 0.25098 1" mesh="xm430-w350-part-4" />
    <geom pos="0.545229 0.400458 -0.106865" quat="0 -0.766044 -0.642788 0" type="mesh" rgba="0.752941 0.752941 0.752941 1" mesh="xm430-w350-part-15" />
    <geom pos="0.651041 0.262755 -0.106865" quat="0 0 1 0" type="mesh" rgba="0.25098 0.25098 0.25098 1" mesh="xm430-w350-part-16" />
    <geom pos="0.651041 0.262755 -0.106865" quat="0 0 1 0" type="mesh" rgba="0.25098 0.25098 0.25098 1" mesh="xm430-w350-part-6" />
    <geom pos="0.545229 0.400458 -0.0968646" quat="0 0.766044 0.642788 0" type="mesh" rgba="0.752941 0.752941 0.752941 1" mesh="xm430-w350-part-1" />
    <geom pos="-0.23297299999999999 0.262755 0.41535700000000003" quat="0.866025 0 0.5 0" type="mesh" rgba="0.25098 0.25098 0.25098 1" mesh="xm430-w350-part-4" />
    <geom pos="-0.180067 0.400458 0.32372100000000004" quat="0.55667 0.383022 0.321394 0.663414" type="mesh" rgba="0.752941 0.752941 0.752941 1" mesh="xm430-w350-part-15" />
    <geom pos="-0.23297299999999999 0.262755 0.41535700000000003" quat="0.866025 0 0.5 0" type="mesh" rgba="0.25098 0.25098 0.25098 1" mesh="xm430-w350-part-16" />
    <geom pos="-0.23297299999999999 0.262755 0.41535700000000003" quat="0.866025 0 0.5 0" type="mesh" rgba="0.25098 0.25098 0.25098 1" mesh="xm430-w350-part-6" />
    <geom pos="-0.18872699999999998 0.400458 0.31872100000000003" quat="0.55667 0.383022 0.321394 0.663414" type="mesh" rgba="0.752941 0.752941 0.752941 1" mesh="xm430-w350-part-1" />
    <geom pos="-0.24322300000000002 0.262755 -0.611332" quat="0.866025 0 -0.5 0" type="mesh" rgba="0.25098 0.25098 0.25098 1" mesh="xm430-w350-part-4" />
    <geom pos="-0.190317 0.400458 -0.5196959999999999" quat="0.55667 -0.383022 -0.321394 0.663414" type="mesh" rgba="0.752941 0.752941 0.752941 1" mesh="xm430-w350-part-15" />
    <geom pos="-0.24322300000000002 0.262755 -0.611332" quat="0.866025 0 -0.5 0" type="mesh" rgba="0.25098 0.25098 0.25098 1" mesh="xm430-w350-part-16" />
    <geom pos="-0.24322300000000002 0.262755 -0.611332" quat="0.866025 0 -0.5 0" type="mesh" rgba="0.25098 0.25098 0.25098 1" mesh="xm430-w350-part-6" />
    <geom pos="-0.181657 0.400458 -0.5246959999999999" quat="0.55667 -0.383022 -0.321394 0.663414" type="mesh" rgba="0.752941 0.752941 0.752941 1" mesh="xm430-w350-part-1" />
    <body name="finger_assembly_-_main" pos="-0.0759867 0.376 0.511613" quat="0.383022 -0.55667 -0.663414 0.321394">
      <inertial pos="0.630768 -0.18482200000000001 0.189935" quat="0.0800809 0.702777 -0.0795419 0.702399" mass="0.034647" diaginertia="5.2637e-05 4.90863e-05 1.16822e-05" />
      <joint name="finger1" pos="0.0 0.0 0.0" axis="0 0 1" actuatorfrcrange="-1 1" />
      <geom pos="0.5 -0.7199850000000001 0.04" quat="0.707107 0 0 -0.707107" type="mesh" rgba="0.301961 0.301961 0.301961 1" mesh="l1" />
      <geom pos="0.5 -0.7199850000000001 0.04" quat="0.707107 0 0 -0.707107" type="mesh" rgba="0.301961 0.301961 0.301961 1" mesh="l2" />
      <geom pos="0.5 -0.7199850000000001 0.04" quat="0.707107 0 0 -0.707107" type="mesh" rgba="0.752941 0.752941 0.752941 1" mesh="tip_shoulder_screw" />

      <flexcomp name="flex_finger1" pos="0.498 -0.722622 0.04" quat="0.707107 0 0 -0.707107" type="gmsh" rgba="0.45098 0.435294 0.435294 1" file="finger6.1_vol.msh" scale=".01 .01 .01">
        <contact condim="6" solref="0.01 1" solimp=".95 .99 .0001" selfcollide="none" />
        <edge damping="1" equality="true" />
        <plugin plugin="mujoco.elasticity.solid">
          <config key="poisson" value="0.2" />
          
          <config key="young" value="5e4" />
        </plugin>
      </flexcomp>
      <geom pos="0.0 0.0 0.19" quat="0.5 -0.5 -0.5 -0.5" type="mesh" rgba="0 0 0 1" mesh="fr12_h101" />
    </body>
    <body name="finger_assembly_-_main_2" pos="0.655908 0.376 -0.290947" quat="0.766044 0 0 0.642788">
      <inertial pos="0.630768 -0.18482200000000001 0.189935" quat="0.0800809 0.702777 -0.0795419 0.702399" mass="0.034647" diaginertia="5.2637e-05 4.90863e-05 1.16822e-05" />
      <joint name="finger2" pos="0.0 0.0 0.0" axis="0 0 1" actuatorfrcrange="-1 1" />
      <geom pos="0.5 -0.7199850000000001 0.04" quat="0.707107 0 0 -0.707107" type="mesh" rgba="0.301961 0.301961 0.301961 1" mesh="l1" />
      <geom pos="0.5 -0.7199850000000001 0.04" quat="0.707107 0 0 -0.707107" type="mesh" rgba="0.301961 0.301961 0.301961 1" mesh="l2" />
      <geom pos="0.5 -0.7199850000000001 0.04" quat="0.707107 0 0 -0.707107" type="mesh" rgba="0.752941 0.752941 0.752941 1" mesh="tip_shoulder_screw" />
      
      <flexcomp name="flex_finger2" pos="0.498 -0.722622 0.04" quat="0.707107 0 0 -0.707107" type="gmsh" rgba="0.45098 0.435294 0.435294 1" file="finger6.1_vol.msh" scale=".01 .01 .01">
        <contact condim="6" solref="0.01 1" solimp=".95 .99 .0001" selfcollide="none" />
        <edge damping="1" equality="true" />
        <plugin plugin="mujoco.elasticity.solid">
          <config key="poisson" value="0.2" />
          
          <config key="young" value="5e4" />
        </plugin>
      </flexcomp>
      <geom pos="0.0 0.0 0.19" quat="0.5 -0.5 -0.5 -0.5" type="mesh" rgba="0 0 0 1" mesh="fr12_h101" />
    </body>
    <body name="finger_assembly_-_main_3" pos="-0.405076 0.376 -0.523506" quat="0.383022 0.55667 0.663414 0.321394">
      <inertial pos="0.630768 -0.18482200000000001 0.189935" quat="0.0800809 0.702777 -0.0795419 0.702399" mass="0.034647" diaginertia="5.2637e-05 4.90863e-05 1.16822e-05" />
      <joint name="finger3" pos="0.0 0.0 0.0" axis="0 0 1" actuatorfrcrange="-1 1" />
      <geom pos="0.5 -0.7199850000000001 0.04" quat="0.707107 0 0 -0.707107" type="mesh" rgba="0.301961 0.301961 0.301961 1" mesh="l1" />
      <geom pos="0.5 -0.7199850000000001 0.04" quat="0.707107 0 0 -0.707107" type="mesh" rgba="0.301961 0.301961 0.301961 1" mesh="l2" />
      <geom pos="0.5 -0.7199850000000001 0.04" quat="0.707107 0 0 -0.707107" type="mesh" rgba="0.752941 0.752941 0.752941 1" mesh="tip_shoulder_screw" />
      
      <flexcomp name="flex_finger3" pos="0.498 -0.722622 0.04" quat="0.707107 0 0 -0.707107" type="gmsh" rgba="0.45098 0.435294 0.435294 1" file="finger6.1_vol.msh" scale=".01 .01 .01">
        <contact condim="6" solref="0.01 1" solimp=".95 .99 .0001" selfcollide="none" />
        <edge damping="1" equality="true" />
        <plugin plugin="mujoco.elasticity.solid">
          <config key="poisson" value="0.2" />
          
          <config key="young" value="5e4" />
        </plugin>
      </flexcomp>
      <geom pos="0.0 0.0 0.19" quat="0.5 -0.5 -0.5 -0.5" type="mesh" rgba="0 0 0 1" mesh="fr12_h101" />
    </body>
  </worldbody>
</mujoco>