<mujoco model="onshape">
  <compiler angle="radian" />
  <asset>
    <mesh name="m3_heat_set_insert" file="m3_heat_set_insert.stl" scale="1000 1000 1000"/>
    <mesh name="ur5_adaptor" file="ur5_adaptor.stl" scale="1000 1000 1000"/>
    <mesh name="ur5_arm_adapter" file="ur5_arm_adapter.stl" scale="1000 1000 1000"/>
    <mesh name="palm_lower" file="palm_lower.stl" scale="1000 1000 1000"/>
    <mesh name="part_1" file="part_1.stl" scale="1000 1000 1000"/>
    <mesh name="palm_base" file="palm_base.stl" scale="1000 1000 1000"/>
    <mesh name="palm_upper" file="palm_upper.stl" scale="1000 1000 1000"/>
    <mesh name="xm430-w350-part-4" file="xm430-w350-part-4.stl" scale="1000 1000 1000"/>
    <mesh name="xm430-w350-part-15" file="xm430-w350-part-15.stl" scale="1000 1000 1000"/>
    <mesh name="xm430-w350-part-16" file="xm430-w350-part-16.stl" scale="1000 1000 1000"/>
    <mesh name="xm430-w350-part-6" file="xm430-w350-part-6.stl" scale="1000 1000 1000"/>
    <mesh name="xm430-w350-part-1" file="xm430-w350-part-1.stl" scale="1000 1000 1000"/>
    <mesh name="l1" file="l1.stl" scale="1000 1000 1000"/>
    <mesh name="l2" file="l2.stl" scale="1000 1000 1000"/>
    <mesh name="tip_shoulder_screw" file="tip_shoulder_screw.stl" scale="1000 1000 1000"/>
    <mesh name="finger_backbone" file="finger_backbone.stl" scale="1000 1000 1000"/>
    <mesh name="fr12_h101" file="fr12_h101.stl" scale="1000 1000 1000"/>
  </asset>
  <worldbody>
    <geom pos="-5.13595 -21.3 -10.0947" quat="0 0 -0.707107 -0.707107" type="mesh" rgba="1 0.756863 0.054902 1" mesh="m3_heat_set_insert" />
    <geom pos="5.82815 0.6 -10.0947" quat="0 0 -0.707107 -0.707107" type="mesh" rgba="0.45098 0.435294 0.435294 1" mesh="ur5_adaptor" />
    <geom pos="-27.0718 -65.194 -10.0947" quat="0 0.707107 0 -0.707107" type="mesh" rgba="0.498039 0.498039 0.498039 1" mesh="ur5_arm_adapter" />
    <geom pos="5.82815 0.6 -10.0947" quat="0 0 0.707107 0.707107" type="mesh" rgba="0.301961 0.301961 0.301961 1" mesh="palm_lower" />
    <geom pos="11.3102 0.0 -0.599467" quat="0 0.258819 0 -0.965926" type="mesh" rgba="0.752941 0.752941 0.752941 1" mesh="part_1" />
    <geom pos="5.82815 0.6 -10.0947" quat="0 0 -0.707107 -0.707107" type="mesh" rgba="0.45098 0.435294 0.435294 1" mesh="palm_base" />
    <geom pos="5.82815 0.6 -10.0947" quat="0.612372 -0.612372 0.353553 0.353553" type="mesh" rgba="0.301961 0.301961 0.301961 1" mesh="palm_upper" />
    <geom pos="-5.13595 0.0 -10.0947" quat="0 0.258819 0 -0.965926" type="mesh" rgba="0.752941 0.752941 0.752941 1" mesh="part_1" />
    <geom pos="11.3102 0.0 -19.5898" quat="0 0.258819 0 -0.965926" type="mesh" rgba="0.752941 0.752941 0.752941 1" mesh="part_1" />
    <geom pos="65.1041 26.2755 -10.6865" quat="0 0 1 0" type="mesh" rgba="0.25098 0.25098 0.25098 1" mesh="xm430-w350-part-4" />
    <geom pos="54.5229 40.0458 -10.6865" quat="0 -0.766044 -0.642788 0" type="mesh" rgba="0.752941 0.752941 0.752941 1" mesh="xm430-w350-part-15" />
    <geom pos="65.1041 26.2755 -10.6865" quat="0 0 1 0" type="mesh" rgba="0.25098 0.25098 0.25098 1" mesh="xm430-w350-part-16" />
    <geom pos="65.1041 26.2755 -10.6865" quat="0 0 1 0" type="mesh" rgba="0.25098 0.25098 0.25098 1" mesh="xm430-w350-part-6" />
    <geom pos="54.5229 40.0458 -9.686459999999999" quat="0 0.766044 0.642788 0" type="mesh" rgba="0.752941 0.752941 0.752941 1" mesh="xm430-w350-part-1" />
    <geom pos="-23.2973 26.2755 41.5357" quat="0.866025 0 0.5 0" type="mesh" rgba="0.25098 0.25098 0.25098 1" mesh="xm430-w350-part-4" />
    <geom pos="-18.006700000000002 40.0458 32.3721" quat="0.55667 0.383022 0.321394 0.663414" type="mesh" rgba="0.752941 0.752941 0.752941 1" mesh="xm430-w350-part-15" />
    <geom pos="-23.2973 26.2755 41.5357" quat="0.866025 0 0.5 0" type="mesh" rgba="0.25098 0.25098 0.25098 1" mesh="xm430-w350-part-16" />
    <geom pos="-23.2973 26.2755 41.5357" quat="0.866025 0 0.5 0" type="mesh" rgba="0.25098 0.25098 0.25098 1" mesh="xm430-w350-part-6" />
    <geom pos="-18.8727 40.0458 31.8721" quat="0.55667 0.383022 0.321394 0.663414" type="mesh" rgba="0.752941 0.752941 0.752941 1" mesh="xm430-w350-part-1" />
    <geom pos="-24.322300000000002 26.2755 -61.1332" quat="0.866025 0 -0.5 0" type="mesh" rgba="0.25098 0.25098 0.25098 1" mesh="xm430-w350-part-4" />
    <geom pos="-19.031699999999997 40.0458 -51.9696" quat="0.55667 -0.383022 -0.321394 0.663414" type="mesh" rgba="0.752941 0.752941 0.752941 1" mesh="xm430-w350-part-15" />
    <geom pos="-24.322300000000002 26.2755 -61.1332" quat="0.866025 0 -0.5 0" type="mesh" rgba="0.25098 0.25098 0.25098 1" mesh="xm430-w350-part-16" />
    <geom pos="-24.322300000000002 26.2755 -61.1332" quat="0.866025 0 -0.5 0" type="mesh" rgba="0.25098 0.25098 0.25098 1" mesh="xm430-w350-part-6" />
    <geom pos="-18.1657 40.0458 -52.4696" quat="0.55667 -0.383022 -0.321394 0.663414" type="mesh" rgba="0.752941 0.752941 0.752941 1" mesh="xm430-w350-part-1" />
    <body name="finger_assembly_-_main" pos="-7.59867 37.6 51.1613" quat="0.383022 -0.55667 -0.663414 0.321394">
      <inertial pos="63.076800000000006 -18.482200000000002 18.9935" quat="0.0800809 0.702777 -0.0795419 0.702399" mass="0.034647" diaginertia="5.2637e-05 4.90863e-05 1.16822e-05" />
      <joint name="finger1" pos="0.0 0.0 0.0" axis="0 0 1" actuatorfrcrange="-1 1" />
      <geom pos="50.0 -71.9985 4.0" quat="0.707107 0 0 -0.707107" type="mesh" rgba="0.301961 0.301961 0.301961 1" mesh="l1" />
      <geom pos="50.0 -71.9985 4.0" quat="0.707107 0 0 -0.707107" type="mesh" rgba="0.301961 0.301961 0.301961 1" mesh="l2" />
      <geom pos="50.0 -71.9985 4.0" quat="0.707107 0 0 -0.707107" type="mesh" rgba="0.752941 0.752941 0.752941 1" mesh="tip_shoulder_screw" />
      <geom pos="49.8 -72.26219999999999 4.0" quat="0.707107 0 0 -0.707107" type="mesh" rgba="0.45098 0.435294 0.435294 1" mesh="finger_backbone" />
      <geom pos="0.0 0.0 19.0" quat="0.5 -0.5 -0.5 -0.5" type="mesh" rgba="0 0 0 1" mesh="fr12_h101" />
    </body>
    <body name="finger_assembly_-_main_2" pos="65.5908 37.6 -29.0947" quat="0.766044 0 0 0.642788">
      <inertial pos="63.076800000000006 -18.482200000000002 18.9935" quat="0.0800809 0.702777 -0.0795419 0.702399" mass="0.034647" diaginertia="5.2637e-05 4.90863e-05 1.16822e-05" />
      <joint name="finger2" pos="0.0 0.0 0.0" axis="0 0 1" actuatorfrcrange="-1 1" />
      <geom pos="50.0 -71.9985 4.0" quat="0.707107 0 0 -0.707107" type="mesh" rgba="0.301961 0.301961 0.301961 1" mesh="l1" />
      <geom pos="50.0 -71.9985 4.0" quat="0.707107 0 0 -0.707107" type="mesh" rgba="0.301961 0.301961 0.301961 1" mesh="l2" />
      <geom pos="50.0 -71.9985 4.0" quat="0.707107 0 0 -0.707107" type="mesh" rgba="0.752941 0.752941 0.752941 1" mesh="tip_shoulder_screw" />
      <geom pos="49.8 -72.26219999999999 4.0" quat="0.707107 0 0 -0.707107" type="mesh" rgba="0.45098 0.435294 0.435294 1" mesh="finger_backbone" />
      <geom pos="0.0 0.0 19.0" quat="0.5 -0.5 -0.5 -0.5" type="mesh" rgba="0 0 0 1" mesh="fr12_h101" />
    </body>
    <body name="finger_assembly_-_main_3" pos="-40.5076 37.6 -52.3506" quat="0.383022 0.55667 0.663414 0.321394">
      <inertial pos="63.076800000000006 -18.482200000000002 18.9935" quat="0.0800809 0.702777 -0.0795419 0.702399" mass="0.034647" diaginertia="5.2637e-05 4.90863e-05 1.16822e-05" />
      <joint name="finger3" pos="0.0 0.0 0.0" axis="0 0 1" actuatorfrcrange="-1 1" />
      <geom pos="50.0 -71.9985 4.0" quat="0.707107 0 0 -0.707107" type="mesh" rgba="0.301961 0.301961 0.301961 1" mesh="l1" />
      <geom pos="50.0 -71.9985 4.0" quat="0.707107 0 0 -0.707107" type="mesh" rgba="0.301961 0.301961 0.301961 1" mesh="l2" />
      <geom pos="50.0 -71.9985 4.0" quat="0.707107 0 0 -0.707107" type="mesh" rgba="0.752941 0.752941 0.752941 1" mesh="tip_shoulder_screw" />
      <geom pos="49.8 -72.26219999999999 4.0" quat="0.707107 0 0 -0.707107" type="mesh" rgba="0.45098 0.435294 0.435294 1" mesh="finger_backbone" />
      <geom pos="0.0 0.0 19.0" quat="0.5 -0.5 -0.5 -0.5" type="mesh" rgba="0 0 0 1" mesh="fr12_h101" />
    </body>
  </worldbody>
</mujoco>